
package com.bittoastergames.projectfruit.lemon.world;

import com.bittoastergames.projectfruit.main.ProjectFruitRegistry;
import net.minecraft.block.Block;
import net.minecraft.init.Blocks;
import net.minecraft.init.Items;
import net.minecraft.item.ItemStack;
import net.minecraft.tileentity.TileEntityChest;
import net.minecraft.world.World;
import net.minecraft.world.gen.feature.WorldGenerator;

import java.util.Random;

public class WorldGenLemonHouse extends WorldGenerator
{
    protected Block[] GetValidSpawnBlocks() {
        return new Block[] {
                ProjectFruitRegistry.lemonilium
        };
    }

    public boolean LocationIsValidSpawn(World world, int i, int j, int k){
        int distanceToAir = 0;
        Block checkID = world.getBlock(i, j, k);

        while (checkID != Blocks.air){
            distanceToAir++;
            checkID = world.getBlock(i, j + distanceToAir, k);
        }

        if (distanceToAir > 1){
            return false;
        }
        j += distanceToAir - 1;

        Block blockID = world.getBlock(i, j, k);
        Block blockIDAbove = world.getBlock(i, j+1, k);
        Block blockIDBelow = world.getBlock(i, j-1, k);
        for (Block x : GetValidSpawnBlocks()){
            if (blockIDAbove != Blocks.air){
                return false;
            }
            if (blockID == x){
                return true;
            }else if (blockID == Blocks.snow && blockIDBelow == x){
                return true;
            }
        }
        return false;
    }

    public WorldGenLemonHouse() { }

    public boolean generate(World world, Random rand, int i, int j, int k) {
        //check that each corner is one of the valid spawn blocks
        if(!LocationIsValidSpawn(world, i, j, k) || !LocationIsValidSpawn(world, i + 20, j, k) || !LocationIsValidSpawn(world, i + 20, j, k + 7) || !LocationIsValidSpawn(world, i, j, k + 7))
        {
            return false;
        }

        TileEntityChest chest = new TileEntityChest();

        TileEntityChest chest2 = new TileEntityChest();

        TileEntityChest chest3 = new TileEntityChest();

        TileEntityChest chest4 = new TileEntityChest();

        Random randChest = new Random();
        for(int slot = 0; slot < chest.getSizeInventory(); slot ++)
        {
            int num = randChest.nextInt(50);
            int num1 = randChest.nextInt(25);
            int num2 = randChest.nextInt(36);
            if(num == 2)
            {
                chest.setInventorySlotContents(slot, new ItemStack(ProjectFruitRegistry.explosiveLemon));
            }
            else if(num == 42 || num == 3)
            {
                int quantity = randChest.nextInt(8) + 1;
                chest.setInventorySlotContents(slot, new ItemStack(ProjectFruitRegistry.lemon, quantity));
            }
            else if(num == 5)
            {
                chest.setInventorySlotContents(slot, new ItemStack(Items.stone_sword));
            }
            else if(num == 24 && num1 == 9)
            {
                chest.setInventorySlotContents(slot, new ItemStack(ProjectFruitRegistry.lemonBow));
            }
            else if(num == 46 && num1 == 8)
            {
                int quantity = randChest.nextInt(16) + 1;
                chest.setInventorySlotContents(slot, new ItemStack(ProjectFruitRegistry.lemonBrick, quantity));
            }
            else if(num == 15 && num1 == 21)
            {
                int quantity = randChest.nextInt(12) + 1;
                chest.setInventorySlotContents(slot, new ItemStack(Items.stick, quantity));
            }
        }

        for(int slot = 0; slot < chest2.getSizeInventory(); slot ++)
        {
            int num = randChest.nextInt(50);
            int num1 = randChest.nextInt(25);
            int num2 = randChest.nextInt(38);
            if(num == 2)
            {
                chest2.setInventorySlotContents(slot, new ItemStack(ProjectFruitRegistry.explosiveLemon));
            }
            else if(num == 42 || num == 3)
            {
                int quantity = randChest.nextInt(5) + 1;
                chest2.setInventorySlotContents(slot, new ItemStack(ProjectFruitRegistry.lemon, quantity));
            }
            else if(num == 5)
            {
                chest2.setInventorySlotContents(slot, new ItemStack(Items.stone_sword));
            }
            else if(num == 32 && num1 == 14)
            {
                chest2.setInventorySlotContents(slot, new ItemStack(Items.stone_axe));
            }
            else if(num == 6 && num1 == 25 && num2 == 12)
            {
                int quantity = randChest.nextInt(8) + 1;
                chest2.setInventorySlotContents(slot, new ItemStack(ProjectFruitRegistry.lemonArrow, quantity));
            }
            else if(num == 0)
            {
                int quantity = randChest.nextInt(8) + 1;
                chest2.setInventorySlotContents(slot, new ItemStack(Items.iron_ingot, quantity));
            }

        }

        for(int slot = 0; slot < chest3.getSizeInventory(); slot ++)
        {
            int num = randChest.nextInt(50);
            int num1 = randChest.nextInt(25);
            int num2 = randChest.nextInt(38);
            int num3 = randChest.nextInt(18);
            if(num == 2)
            {
                chest3.setInventorySlotContents(slot, new ItemStack(ProjectFruitRegistry.explosiveLemon));
            }
            else if(num == 42 || num == 3)
            {
                int quantity = randChest.nextInt(14) + 1;
                chest3.setInventorySlotContents(slot, new ItemStack(ProjectFruitRegistry.lemon, quantity));
            }
            else if(num == 5 && num1 == 14)
            {
                chest3.setInventorySlotContents(slot, new ItemStack(Items.stone_sword));
            }
            else if(num == 24 && num1 == 7)
            {
                chest3.setInventorySlotContents(slot, new ItemStack(ProjectFruitRegistry.lemonBow));
            }
            else if(num == 43 && num1 == 14 && num2 == 32 && num3 == 4)
            {
                chest3.setInventorySlotContents(slot, new ItemStack(ProjectFruitRegistry.lemonSword));
            }
            else if(num == 45 && num1 == 23)
            {
                int quantity = randChest.nextInt(8) + 1;
                chest3.setInventorySlotContents(slot, new ItemStack(Blocks.glass, quantity));
            }
            else if(num == 37 && num1 == 5 && num2 == 19 && num3 == 10)
            {
                chest.setInventorySlotContents(slot, new ItemStack(Items.iron_pickaxe));
            }
        }

        for(int slot = 0; slot < chest4.getSizeInventory(); slot ++)
        {
            int num = randChest.nextInt(50);
            int num1 = randChest.nextInt(25);
            int num2 = randChest.nextInt(38);
            if(num == 2)
            {
                chest4.setInventorySlotContents(slot, new ItemStack(ProjectFruitRegistry.explosiveLemon));
            }
            else if(num == 42 || num == 3)
            {
                int quantity = randChest.nextInt(6) + 1;
                chest4.setInventorySlotContents(slot, new ItemStack(ProjectFruitRegistry.lemon, quantity));
            }
            else if(num == 5)
            {
                chest4.setInventorySlotContents(slot, new ItemStack(Items.stone_sword));
            }
            else if(num == 41 && num1 == 20)
            {
                chest4.setInventorySlotContents(slot, new ItemStack(Items.stone_pickaxe));
            }
            else if(num == 28 && num1 == 17)
            {
                int quantity = randChest.nextInt(18) + 1;
                chest4.setInventorySlotContents(slot, new ItemStack(Items.coal, quantity));
            }
            else if(num == 24 && num1 == 11 && num2 == 31)
            {
                int quantity = randChest.nextInt(6) + 1;
                chest4.setInventorySlotContents(slot, new ItemStack(Items.gunpowder, quantity));
            }
        }

        world.setBlock(i + 0, j + 0, k + 7, Blocks.air);
        world.setBlock(i + 0, j + 1, k + 7, Blocks.air);
        world.setBlock(i + 0, j + 2, k + 7, Blocks.air);
        world.setBlock(i + 0, j + 3, k + 7, Blocks.air);
        world.setBlock(i + 0, j + 4, k + 0, Blocks.air);
        world.setBlock(i + 0, j + 4, k + 1, Blocks.air);
        world.setBlock(i + 0, j + 4, k + 2, Blocks.air);
        world.setBlock(i + 0, j + 4, k + 3, ProjectFruitRegistry.lemonBrick);
        world.setBlock(i + 0, j + 4, k + 4, ProjectFruitRegistry.lemonBrick);
        world.setBlock(i + 0, j + 4, k + 5, Blocks.air);
        world.setBlock(i + 0, j + 4, k + 6, Blocks.air);
        world.setBlock(i + 0, j + 4, k + 7, Blocks.air);
        world.setBlock(i + 0, j + 5, k + 0, Blocks.air);
        world.setBlock(i + 0, j + 5, k + 1, Blocks.air);
        world.setBlock(i + 0, j + 5, k + 2, Blocks.air);
        world.setBlock(i + 0, j + 5, k + 3, Blocks.air);
        world.setBlock(i + 0, j + 5, k + 4, Blocks.air);
        world.setBlock(i + 0, j + 5, k + 5, Blocks.air);
        world.setBlock(i + 0, j + 5, k + 6, Blocks.air);
        world.setBlock(i + 0, j + 5, k + 7, Blocks.air);
        world.setBlock(i + 0, j + 6, k + 0, Blocks.air);
        world.setBlock(i + 0, j + 6, k + 1, Blocks.air);
        world.setBlock(i + 0, j + 6, k + 2, Blocks.air);
        world.setBlock(i + 0, j + 6, k + 3, Blocks.air);
        world.setBlock(i + 0, j + 6, k + 4, Blocks.air);
        world.setBlock(i + 0, j + 6, k + 5, Blocks.air);
        world.setBlock(i + 0, j + 6, k + 6, Blocks.air);
        world.setBlock(i + 0, j + 6, k + 7, Blocks.air);
        world.setBlock(i + 0, j + 7, k + 0, Blocks.air);
        world.setBlock(i + 0, j + 7, k + 1, Blocks.air);
        world.setBlock(i + 0, j + 7, k + 2, Blocks.air);
        world.setBlock(i + 0, j + 7, k + 3, Blocks.air);
        world.setBlock(i + 0, j + 7, k + 4, Blocks.air);
        world.setBlock(i + 0, j + 7, k + 5, Blocks.air);
        world.setBlock(i + 0, j + 7, k + 6, Blocks.air);
        world.setBlock(i + 0, j + 7, k + 7, Blocks.air);
        world.setBlock(i + 0, j + 8, k + 0, Blocks.air);
        world.setBlock(i + 0, j + 8, k + 1, Blocks.air);
        world.setBlock(i + 0, j + 8, k + 2, Blocks.air);
        world.setBlock(i + 0, j + 8, k + 3, Blocks.air);
        world.setBlock(i + 0, j + 8, k + 4, Blocks.air);
        world.setBlock(i + 0, j + 8, k + 5, Blocks.air);
        world.setBlock(i + 0, j + 8, k + 6, Blocks.air);
        world.setBlock(i + 0, j + 8, k + 7, Blocks.air);
        world.setBlock(i + 1, j + 0, k + 7, Blocks.air);
        world.setBlock(i + 1, j + 1, k + 7, Blocks.air);
        world.setBlock(i + 1, j + 2, k + 7, Blocks.air);
        world.setBlock(i + 1, j + 3, k + 3, ProjectFruitRegistry.lemonBrick);
        world.setBlock(i + 1, j + 3, k + 4, ProjectFruitRegistry.lemonBrick);
        world.setBlock(i + 1, j + 3, k + 7, Blocks.air);
        world.setBlock(i + 1, j + 4, k + 0, Blocks.air);
        world.setBlock(i + 1, j + 4, k + 1, Blocks.air);
        world.setBlock(i + 1, j + 4, k + 2, ProjectFruitRegistry.lemonBrick);
        world.setBlock(i + 1, j + 4, k + 3, ProjectFruitRegistry.lemonBrick);
        world.setBlock(i + 1, j + 4, k + 4, ProjectFruitRegistry.lemonBrick);
        world.setBlock(i + 1, j + 4, k + 5, ProjectFruitRegistry.lemonBrick);
        world.setBlock(i + 1, j + 4, k + 6, Blocks.air);
        world.setBlock(i + 1, j + 4, k + 7, Blocks.air);
        world.setBlock(i + 1, j + 5, k + 0, Blocks.air);
        world.setBlock(i + 1, j + 5, k + 1, Blocks.air);
        world.setBlock(i + 1, j + 5, k + 2, Blocks.air);
        world.setBlock(i + 1, j + 5, k + 3, ProjectFruitRegistry.lemonBrick);
        world.setBlock(i + 1, j + 5, k + 4, ProjectFruitRegistry.lemonBrick);
        world.setBlock(i + 1, j + 5, k + 5, Blocks.air);
        world.setBlock(i + 1, j + 5, k + 6, Blocks.air);
        world.setBlock(i + 1, j + 5, k + 7, Blocks.air);
        world.setBlock(i + 1, j + 6, k + 0, Blocks.air);
        world.setBlock(i + 1, j + 6, k + 1, Blocks.air);
        world.setBlock(i + 1, j + 6, k + 2, Blocks.air);
        world.setBlock(i + 1, j + 6, k + 3, Blocks.air);
        world.setBlock(i + 1, j + 6, k + 4, Blocks.air);
        world.setBlock(i + 1, j + 6, k + 5, Blocks.air);
        world.setBlock(i + 1, j + 6, k + 6, Blocks.air);
        world.setBlock(i + 1, j + 6, k + 7, Blocks.air);
        world.setBlock(i + 1, j + 7, k + 0, Blocks.air);
        world.setBlock(i + 1, j + 7, k + 1, Blocks.air);
        world.setBlock(i + 1, j + 7, k + 2, Blocks.air);
        world.setBlock(i + 1, j + 7, k + 3, Blocks.air);
        world.setBlock(i + 1, j + 7, k + 4, Blocks.air);
        world.setBlock(i + 1, j + 7, k + 5, Blocks.air);
        world.setBlock(i + 1, j + 7, k + 6, Blocks.air);
        world.setBlock(i + 1, j + 7, k + 7, Blocks.air);
        world.setBlock(i + 1, j + 8, k + 0, Blocks.air);
        world.setBlock(i + 1, j + 8, k + 1, Blocks.air);
        world.setBlock(i + 1, j + 8, k + 2, Blocks.air);
        world.setBlock(i + 1, j + 8, k + 3, Blocks.air);
        world.setBlock(i + 1, j + 8, k + 4, Blocks.air);
        world.setBlock(i + 1, j + 8, k + 5, Blocks.air);
        world.setBlock(i + 1, j + 8, k + 6, Blocks.air);
        world.setBlock(i + 1, j + 8, k + 7, Blocks.air);
        world.setBlock(i + 2, j + 0, k + 7, Blocks.air);
        world.setBlock(i + 2, j + 1, k + 7, Blocks.air);
        world.setBlock(i + 2, j + 2, k + 3, ProjectFruitRegistry.lemonBrick);
        world.setBlock(i + 2, j + 2, k + 4, ProjectFruitRegistry.lemonBrick);
        world.setBlock(i + 2, j + 2, k + 7, Blocks.air);
        world.setBlock(i + 2, j + 3, k + 2, ProjectFruitRegistry.lemonBrick);
        world.setBlock(i + 2, j + 3, k + 3, ProjectFruitRegistry.lemonBrick);
        world.setBlock(i + 2, j + 3, k + 4, ProjectFruitRegistry.lemonBrick);
        world.setBlock(i + 2, j + 3, k + 5, ProjectFruitRegistry.lemonBrick);
        world.setBlock(i + 2, j + 3, k + 7, Blocks.air);
        world.setBlock(i + 2, j + 4, k + 0, Blocks.air);
        world.setBlock(i + 2, j + 4, k + 1, ProjectFruitRegistry.lemonBrick);
        world.setBlock(i + 2, j + 4, k + 2, ProjectFruitRegistry.lemonBrick);
        world.setBlock(i + 2, j + 4, k + 3, Blocks.planks);
        world.setBlock(i + 2, j + 4, k + 4, Blocks.planks);
        world.setBlock(i + 2, j + 4, k + 5, ProjectFruitRegistry.lemonBrick);
        world.setBlock(i + 2, j + 4, k + 6, ProjectFruitRegistry.lemonBrick);
        world.setBlock(i + 2, j + 4, k + 7, Blocks.air);
        world.setBlock(i + 2, j + 5, k + 0, Blocks.air);
        world.setBlock(i + 2, j + 5, k + 1, Blocks.air);
        world.setBlock(i + 2, j + 5, k + 2, ProjectFruitRegistry.lemonBrick);
        world.setBlock(i + 2, j + 5, k + 3, Blocks.bookshelf);
        world.setBlock(i + 2, j + 5, k + 4, Blocks.bookshelf);
        world.setBlock(i + 2, j + 5, k + 5, ProjectFruitRegistry.lemonBrick);
        world.setBlock(i + 2, j + 5, k + 6, Blocks.air);
        world.setBlock(i + 2, j + 5, k + 7, Blocks.air);
        world.setBlock(i + 2, j + 6, k + 0, Blocks.air);
        world.setBlock(i + 2, j + 6, k + 1, Blocks.air);
        world.setBlock(i + 2, j + 6, k + 2, Blocks.air);
        world.setBlock(i + 2, j + 6, k + 3, ProjectFruitRegistry.lemonBrick);
        world.setBlock(i + 2, j + 6, k + 4, ProjectFruitRegistry.lemonBrick);
        world.setBlock(i + 2, j + 6, k + 5, Blocks.air);
        world.setBlock(i + 2, j + 6, k + 6, Blocks.air);
        world.setBlock(i + 2, j + 6, k + 7, Blocks.air);
        world.setBlock(i + 2, j + 7, k + 0, Blocks.air);
        world.setBlock(i + 2, j + 7, k + 1, Blocks.air);
        world.setBlock(i + 2, j + 7, k + 2, Blocks.air);
        world.setBlock(i + 2, j + 7, k + 3, Blocks.air);
        world.setBlock(i + 2, j + 7, k + 4, Blocks.air);
        world.setBlock(i + 2, j + 7, k + 5, Blocks.air);
        world.setBlock(i + 2, j + 7, k + 6, Blocks.air);
        world.setBlock(i + 2, j + 7, k + 7, Blocks.air);
        world.setBlock(i + 2, j + 8, k + 0, Blocks.air);
        world.setBlock(i + 2, j + 8, k + 1, Blocks.air);
        world.setBlock(i + 2, j + 8, k + 2, Blocks.air);
        world.setBlock(i + 2, j + 8, k + 3, Blocks.air);
        world.setBlock(i + 2, j + 8, k + 4, Blocks.air);
        world.setBlock(i + 2, j + 8, k + 5, Blocks.air);
        world.setBlock(i + 2, j + 8, k + 6, Blocks.air);
        world.setBlock(i + 2, j + 8, k + 7, Blocks.air);
        world.setBlock(i + 3, j + 0, k + 7, Blocks.air);
        world.setBlock(i + 3, j + 1, k + 3, ProjectFruitRegistry.lemonBrick);
        world.setBlock(i + 3, j + 1, k + 4, ProjectFruitRegistry.lemonBrick);
        world.setBlock(i + 3, j + 1, k + 7, Blocks.air);
        world.setBlock(i + 3, j + 2, k + 2, ProjectFruitRegistry.lemonBrick);
        world.setBlock(i + 3, j + 2, k + 3, ProjectFruitRegistry.lemonBrick);
        world.setBlock(i + 3, j + 2, k + 4, ProjectFruitRegistry.lemonBrick);
        world.setBlock(i + 3, j + 2, k + 5, ProjectFruitRegistry.lemonBrick);
        world.setBlock(i + 3, j + 2, k + 7, Blocks.air);
        world.setBlock(i + 3, j + 3, k + 1, ProjectFruitRegistry.lemonBrick);
        world.setBlock(i + 3, j + 3, k + 2, ProjectFruitRegistry.lemonBrick);
        world.setBlock(i + 3, j + 3, k + 3, ProjectFruitRegistry.lemonBrick);
        world.setBlock(i + 3, j + 3, k + 4, ProjectFruitRegistry.lemonBrick);
        world.setBlock(i + 3, j + 3, k + 5, ProjectFruitRegistry.lemonBrick);
        world.setBlock(i + 3, j + 3, k + 6, ProjectFruitRegistry.lemonBrick);
        world.setBlock(i + 3, j + 3, k + 7, Blocks.air);
        world.setBlock(i + 3, j + 4, k + 0, ProjectFruitRegistry.lemonBrick);
        world.setBlock(i + 3, j + 4, k + 1, ProjectFruitRegistry.lemonBrick);
        world.setBlock(i + 3, j + 4, k + 2, Blocks.planks);
        world.setBlock(i + 3, j + 4, k + 3, Blocks.planks);
        world.setBlock(i + 3, j + 4, k + 4, Blocks.planks);
        world.setBlock(i + 3, j + 4, k + 5, Blocks.planks);
        world.setBlock(i + 3, j + 4, k + 6, ProjectFruitRegistry.lemonBrick);
        world.setBlock(i + 3, j + 4, k + 7, ProjectFruitRegistry.lemonBrick);
        world.setBlock(i + 3, j + 5, k + 0, Blocks.air);
        world.setBlock(i + 3, j + 5, k + 1, ProjectFruitRegistry.lemonBrick);
        world.setBlock(i + 3, j + 5, k + 2, Blocks.bookshelf);
        world.setBlock(i + 3, j + 5, k + 3, Blocks.air);
        world.setBlock(i + 3, j + 5, k + 4, Blocks.air);
        world.setBlock(i + 3, j + 5, k + 5, Blocks.bookshelf);
        world.setBlock(i + 3, j + 5, k + 6, ProjectFruitRegistry.lemonBrick);
        world.setBlock(i + 3, j + 5, k + 7, Blocks.air);
        world.setBlock(i + 3, j + 6, k + 0, Blocks.air);
        world.setBlock(i + 3, j + 6, k + 1, Blocks.air);
        world.setBlock(i + 3, j + 6, k + 2, ProjectFruitRegistry.lemonBrick);
        world.setBlock(i + 3, j + 6, k + 3, Blocks.air);
        world.setBlock(i + 3, j + 6, k + 4, Blocks.air);
        world.setBlock(i + 3, j + 6, k + 5, ProjectFruitRegistry.lemonBrick);
        world.setBlock(i + 3, j + 6, k + 6, Blocks.air);
        world.setBlock(i + 3, j + 6, k + 7, Blocks.air);
        world.setBlock(i + 3, j + 7, k + 0, Blocks.air);
        world.setBlock(i + 3, j + 7, k + 1, Blocks.air);
        world.setBlock(i + 3, j + 7, k + 2, Blocks.air);
        world.setBlock(i + 3, j + 7, k + 3, ProjectFruitRegistry.lemonBrick);
        world.setBlock(i + 3, j + 7, k + 4, ProjectFruitRegistry.lemonBrick);
        world.setBlock(i + 3, j + 7, k + 5, Blocks.air);
        world.setBlock(i + 3, j + 7, k + 6, Blocks.air);
        world.setBlock(i + 3, j + 7, k + 7, Blocks.air);
        world.setBlock(i + 3, j + 8, k + 0, Blocks.air);
        world.setBlock(i + 3, j + 8, k + 1, Blocks.air);
        world.setBlock(i + 3, j + 8, k + 2, Blocks.air);
        world.setBlock(i + 3, j + 8, k + 3, Blocks.air);
        world.setBlock(i + 3, j + 8, k + 4, Blocks.air);
        world.setBlock(i + 3, j + 8, k + 5, Blocks.air);
        world.setBlock(i + 3, j + 8, k + 6, Blocks.air);
        world.setBlock(i + 3, j + 8, k + 7, Blocks.air);
        world.setBlock(i + 4, j + 0, k + 0, ProjectFruitRegistry.lemonBrick);
        world.setBlock(i + 4, j + 0, k + 1, ProjectFruitRegistry.lemonBrick);
        world.setBlock(i + 4, j + 0, k + 2, ProjectFruitRegistry.lemonBrick);
        world.setBlock(i + 4, j + 0, k + 3, ProjectFruitRegistry.lemonBrick);
        world.setBlock(i + 4, j + 0, k + 4, ProjectFruitRegistry.lemonBrick);
        world.setBlock(i + 4, j + 0, k + 5, ProjectFruitRegistry.lemonBrick);
        world.setBlock(i + 4, j + 0, k + 6, ProjectFruitRegistry.lemonBrick);
        world.setBlock(i + 4, j + 0, k + 7, ProjectFruitRegistry.lemonBrick);
        world.setBlock(i + 4, j + 1, k + 0, ProjectFruitRegistry.lemonBrick);
        world.setBlock(i + 4, j + 1, k + 1, ProjectFruitRegistry.lemonBrick);
        world.setBlock(i + 4, j + 1, k + 2, ProjectFruitRegistry.lemonBrick);
        world.setBlock(i + 4, j + 1, k + 3, ProjectFruitRegistry.lemonBrick);
        world.setBlock(i + 4, j + 1, k + 4, ProjectFruitRegistry.lemonBrick);
        world.setBlock(i + 4, j + 1, k + 5, ProjectFruitRegistry.lemonBrick);
        world.setBlock(i + 4, j + 1, k + 6, ProjectFruitRegistry.lemonBrick);
        world.setBlock(i + 4, j + 1, k + 7, ProjectFruitRegistry.lemonBrick);
        world.setBlock(i + 4, j + 2, k + 0, ProjectFruitRegistry.lemonBrick);
        world.setBlock(i + 4, j + 2, k + 1, ProjectFruitRegistry.lemonBrick);
        world.setBlock(i + 4, j + 2, k + 2, ProjectFruitRegistry.lemonBrick);
        world.setBlock(i + 4, j + 2, k + 3, ProjectFruitRegistry.lemonBrick);
        world.setBlock(i + 4, j + 2, k + 4, ProjectFruitRegistry.lemonBrick);
        world.setBlock(i + 4, j + 2, k + 5, ProjectFruitRegistry.lemonBrick);
        world.setBlock(i + 4, j + 2, k + 6, ProjectFruitRegistry.lemonBrick);
        world.setBlock(i + 4, j + 2, k + 7, ProjectFruitRegistry.lemonBrick);
        world.setBlock(i + 4, j + 3, k + 0, ProjectFruitRegistry.lemonBrick);
        world.setBlock(i + 4, j + 3, k + 1, ProjectFruitRegistry.lemonBrick);
        world.setBlock(i + 4, j + 3, k + 2, ProjectFruitRegistry.lemonBrick);
        world.setBlock(i + 4, j + 3, k + 3, ProjectFruitRegistry.lemonBrick);
        world.setBlock(i + 4, j + 3, k + 4, ProjectFruitRegistry.lemonBrick);
        world.setBlock(i + 4, j + 3, k + 5, ProjectFruitRegistry.lemonBrick);
        world.setBlock(i + 4, j + 3, k + 6, ProjectFruitRegistry.lemonBrick);
        world.setBlock(i + 4, j + 3, k + 7, ProjectFruitRegistry.lemonBrick);
        world.setBlock(i + 4, j + 4, k + 0, ProjectFruitRegistry.lemonBrick);
        world.setBlock(i + 4, j + 4, k + 1, Blocks.planks);
        world.setBlock(i + 4, j + 4, k + 2, Blocks.planks);
        world.setBlock(i + 4, j + 4, k + 3, Blocks.planks);
        world.setBlock(i + 4, j + 4, k + 4, Blocks.planks);
        world.setBlock(i + 4, j + 4, k + 5, Blocks.planks);
        world.setBlock(i + 4, j + 4, k + 6, Blocks.planks);
        world.setBlock(i + 4, j + 4, k + 7, ProjectFruitRegistry.lemonBrick);
        world.setBlock(i + 4, j + 5, k + 0, ProjectFruitRegistry.lemonBrick);
        world.setBlock(i + 4, j + 5, k + 1, Blocks.bookshelf);
        world.setBlock(i + 4, j + 5, k + 2, Blocks.air);
        world.setBlock(i + 4, j + 5, k + 3, Blocks.air);
        world.setBlock(i + 4, j + 5, k + 4, Blocks.air);
        world.setBlock(i + 4, j + 5, k + 5, Blocks.air);
        world.setBlock(i + 4, j + 5, k + 6, Blocks.bookshelf);
        world.setBlock(i + 4, j + 5, k + 7, ProjectFruitRegistry.lemonBrick);
        world.setBlock(i + 4, j + 6, k + 0, Blocks.air);
        world.setBlock(i + 4, j + 6, k + 1, ProjectFruitRegistry.lemonBrick);
        world.setBlock(i + 4, j + 6, k + 2, Blocks.air);
        world.setBlock(i + 4, j + 6, k + 3, Blocks.air);
        world.setBlock(i + 4, j + 6, k + 4, Blocks.air);
        world.setBlock(i + 4, j + 6, k + 5, Blocks.air);
        world.setBlock(i + 4, j + 6, k + 6, ProjectFruitRegistry.lemonBrick);
        world.setBlock(i + 4, j + 6, k + 7, Blocks.air);
        world.setBlock(i + 4, j + 7, k + 0, Blocks.air);
        world.setBlock(i + 4, j + 7, k + 1, Blocks.air);
        world.setBlock(i + 4, j + 7, k + 2, ProjectFruitRegistry.lemonBrick);
        world.setBlock(i + 4, j + 7, k + 3, Blocks.air);
        world.setBlock(i + 4, j + 7, k + 4, Blocks.air);
        world.setBlock(i + 4, j + 7, k + 5, ProjectFruitRegistry.lemonBrick);
        world.setBlock(i + 4, j + 7, k + 6, Blocks.air);
        world.setBlock(i + 4, j + 7, k + 7, Blocks.air);
        world.setBlock(i + 4, j + 8, k + 0, Blocks.air);
        world.setBlock(i + 4, j + 8, k + 1, Blocks.air);
        world.setBlock(i + 4, j + 8, k + 2, Blocks.air);
        world.setBlock(i + 4, j + 8, k + 3, ProjectFruitRegistry.lemonBrick);
        world.setBlock(i + 4, j + 8, k + 4, ProjectFruitRegistry.lemonBrick);
        world.setBlock(i + 4, j + 8, k + 5, Blocks.air);
        world.setBlock(i + 4, j + 8, k + 6, Blocks.air);
        world.setBlock(i + 4, j + 8, k + 7, Blocks.air);
        world.setBlock(i + 5, j + 0, k + 0, ProjectFruitRegistry.lemonBrick);
        world.setBlock(i + 5, j + 0, k + 1, Blocks.planks);
        world.setBlock(i + 5, j + 0, k + 2, Blocks.planks);
        world.setBlock(i + 5, j + 0, k + 3, Blocks.planks);
        world.setBlock(i + 5, j + 0, k + 4, Blocks.planks);
        world.setBlock(i + 5, j + 0, k + 5, Blocks.planks);
        world.setBlock(i + 5, j + 0, k + 6, Blocks.planks);
        world.setBlock(i + 5, j + 0, k + 7, ProjectFruitRegistry.lemonBrick);
        world.setBlock(i + 5, j + 1, k + 0, ProjectFruitRegistry.lemonBrick);
        world.setBlock(i + 5, j + 1, k + 1, Blocks.air);
        world.setBlock(i + 5, j + 1, k + 2, Blocks.air);
        world.setBlock(i + 5, j + 1, k + 3, Blocks.air);
        world.setBlock(i + 5, j + 1, k + 4, Blocks.air);
        world.setBlock(i + 5, j + 1, k + 5, Blocks.air);
        world.setBlock(i + 5, j + 1, k + 6, Blocks.air);
        world.setBlock(i + 5, j + 1, k + 7, ProjectFruitRegistry.lemonBrick);
        world.setBlock(i + 5, j + 2, k + 0, ProjectFruitRegistry.lemonBrick);
        world.setBlock(i + 5, j + 2, k + 1, Blocks.air);
        world.setBlock(i + 5, j + 2, k + 2, Blocks.air);
        world.setBlock(i + 5, j + 2, k + 3, Blocks.air);
        world.setBlock(i + 5, j + 2, k + 4, Blocks.air);
        world.setBlock(i + 5, j + 2, k + 5, Blocks.air);
        world.setBlock(i + 5, j + 2, k + 6, Blocks.air);
        world.setBlock(i + 5, j + 2, k + 7, ProjectFruitRegistry.lemonBrick);
        world.setBlock(i + 5, j + 3, k + 0, ProjectFruitRegistry.lemonBrick);
        world.setBlock(i + 5, j + 3, k + 1, Blocks.air);
        world.setBlock(i + 5, j + 3, k + 2, Blocks.air);
        world.setBlock(i + 5, j + 3, k + 3, Blocks.air);
        world.setBlock(i + 5, j + 3, k + 4, Blocks.air);
        world.setBlock(i + 5, j + 3, k + 5, Blocks.air);
        world.setBlock(i + 5, j + 3, k + 6, Blocks.air);
        world.setBlock(i + 5, j + 3, k + 7, ProjectFruitRegistry.lemonBrick);
        world.setBlock(i + 5, j + 4, k + 0, ProjectFruitRegistry.lemonBrick);
        world.setBlock(i + 5, j + 4, k + 1, Blocks.glowstone);
        world.setBlock(i + 5, j + 4, k + 2, Blocks.planks);
        world.setBlock(i + 5, j + 4, k + 3, Blocks.air);
        world.setBlock(i + 5, j + 4, k + 4, Blocks.air);
        world.setBlock(i + 5, j + 4, k + 5, Blocks.planks);
        world.setBlock(i + 5, j + 4, k + 6, Blocks.glowstone);
        world.setBlock(i + 5, j + 4, k + 7, ProjectFruitRegistry.lemonBrick);
        world.setBlock(i + 5, j + 5, k + 0, ProjectFruitRegistry.lemonBrick);
        world.setBlock(i + 5, j + 5, k + 1, Blocks.chest);
        world.setTileEntity(i + 5, j + 5, k + 1, chest);
        world.setBlockMetadataWithNotify(i + 5, j + 5, k + 1, 3, 2);
        world.setBlock(i + 5, j + 5, k + 2, Blocks.air);
        world.setBlock(i + 5, j + 5, k + 3, Blocks.air);
        world.setBlock(i + 5, j + 5, k + 4, Blocks.air);
        world.setBlock(i + 5, j + 5, k + 5, Blocks.air);
        world.setBlock(i + 5, j + 5, k + 6, Blocks.chest);
        world.setTileEntity(i + 5, j + 5, k + 6, chest2);
        world.setBlockMetadataWithNotify(i + 5, j + 5, k + 6, 2, 2);
        world.setBlock(i + 5, j + 5, k + 7, ProjectFruitRegistry.lemonBrick);
        world.setBlock(i + 5, j + 6, k + 0, ProjectFruitRegistry.lemonBrick);
        world.setBlock(i + 5, j + 6, k + 1, Blocks.wooden_slab);
        world.setBlock(i + 5, j + 6, k + 2, Blocks.air);
        world.setBlock(i + 5, j + 6, k + 3, Blocks.air);
        world.setBlock(i + 5, j + 6, k + 4, Blocks.air);
        world.setBlock(i + 5, j + 6, k + 5, Blocks.air);
        world.setBlock(i + 5, j + 6, k + 6, Blocks.wooden_slab);
        world.setBlock(i + 5, j + 6, k + 7, ProjectFruitRegistry.lemonBrick);
        world.setBlock(i + 5, j + 7, k + 0, Blocks.air);
        world.setBlock(i + 5, j + 7, k + 1, ProjectFruitRegistry.lemonBrick);
        world.setBlock(i + 5, j + 7, k + 2, Blocks.air);
        world.setBlock(i + 5, j + 7, k + 3, Blocks.air);
        world.setBlock(i + 5, j + 7, k + 4, Blocks.air);
        world.setBlock(i + 5, j + 7, k + 5, Blocks.air);
        world.setBlock(i + 5, j + 7, k + 6, ProjectFruitRegistry.lemonBrick);
        world.setBlock(i + 5, j + 7, k + 7, Blocks.air);
        world.setBlock(i + 5, j + 8, k + 0, Blocks.air);
        world.setBlock(i + 5, j + 8, k + 1, Blocks.air);
        world.setBlock(i + 5, j + 8, k + 2, ProjectFruitRegistry.lemonBrick);
        world.setBlock(i + 5, j + 8, k + 3, Blocks.glowstone);
        world.setBlock(i + 5, j + 8, k + 4, Blocks.glowstone);
        world.setBlock(i + 5, j + 8, k + 5, ProjectFruitRegistry.lemonBrick);
        world.setBlock(i + 5, j + 8, k + 6, Blocks.air);
        world.setBlock(i + 5, j + 8, k + 7, Blocks.air);
        world.setBlock(i + 6, j + 0, k + 0, ProjectFruitRegistry.lemonBrick);
        world.setBlock(i + 6, j + 0, k + 1, Blocks.planks);
        world.setBlock(i + 6, j + 0, k + 2, Blocks.planks);
        world.setBlock(i + 6, j + 0, k + 3, Blocks.planks);
        world.setBlock(i + 6, j + 0, k + 4, Blocks.planks);
        world.setBlock(i + 6, j + 0, k + 5, Blocks.planks);
        world.setBlock(i + 6, j + 0, k + 6, Blocks.planks);
        world.setBlock(i + 6, j + 0, k + 7, ProjectFruitRegistry.lemonBrick);
        world.setBlock(i + 6, j + 1, k + 0, ProjectFruitRegistry.lemonBrick);
        world.setBlock(i + 6, j + 1, k + 1, Blocks.air);
        world.setBlock(i + 6, j + 1, k + 2, Blocks.air);
        world.setBlock(i + 6, j + 1, k + 3, Blocks.oak_stairs);
        world.setBlock(i + 6, j + 1, k + 4, Blocks.oak_stairs);
        world.setBlock(i + 6, j + 1, k + 5, Blocks.air);
        world.setBlock(i + 6, j + 1, k + 6, Blocks.air);
        world.setBlock(i + 6, j + 1, k + 7, ProjectFruitRegistry.lemonBrick);
        world.setBlock(i + 6, j + 2, k + 0, ProjectFruitRegistry.lemonBrick);
        world.setBlock(i + 6, j + 2, k + 1, Blocks.air);
        world.setBlock(i + 6, j + 2, k + 2, Blocks.air);
        world.setBlock(i + 6, j + 2, k + 3, Blocks.air);
        world.setBlock(i + 6, j + 2, k + 4, Blocks.air);
        world.setBlock(i + 6, j + 2, k + 5, Blocks.air);
        world.setBlock(i + 6, j + 2, k + 6, Blocks.air);
        world.setBlock(i + 6, j + 2, k + 7, ProjectFruitRegistry.lemonBrick);
        world.setBlock(i + 6, j + 3, k + 0, ProjectFruitRegistry.lemonBrick);
        world.setBlock(i + 6, j + 3, k + 1, Blocks.air);
        world.setBlock(i + 6, j + 3, k + 2, Blocks.air);
        world.setBlock(i + 6, j + 3, k + 3, Blocks.air);
        world.setBlock(i + 6, j + 3, k + 4, Blocks.air);
        world.setBlock(i + 6, j + 3, k + 5, Blocks.air);
        world.setBlock(i + 6, j + 3, k + 6, Blocks.air);
        world.setBlock(i + 6, j + 3, k + 7, ProjectFruitRegistry.lemonBrick);
        world.setBlock(i + 6, j + 4, k + 0, ProjectFruitRegistry.lemonBrick);
        world.setBlock(i + 6, j + 4, k + 1, Blocks.planks);
        world.setBlock(i + 6, j + 4, k + 2, Blocks.planks);
        world.setBlock(i + 6, j + 4, k + 3, Blocks.air);
        world.setBlock(i + 6, j + 4, k + 4, Blocks.air);
        world.setBlock(i + 6, j + 4, k + 5, Blocks.planks);
        world.setBlock(i + 6, j + 4, k + 6, Blocks.planks);
        world.setBlock(i + 6, j + 4, k + 7, ProjectFruitRegistry.lemonBrick);
        world.setBlock(i + 6, j + 5, k + 0, ProjectFruitRegistry.lemonBrick);
        world.setBlock(i + 6, j + 5, k + 1, Blocks.oak_stairs);
        world.setBlock(i + 6, j + 5, k + 2, Blocks.air);
        world.setBlock(i + 6, j + 5, k + 3, Blocks.air);
        world.setBlock(i + 6, j + 5, k + 4, Blocks.air);
        world.setBlock(i + 6, j + 5, k + 5, Blocks.air);
        world.setBlock(i + 6, j + 5, k + 6, Blocks.oak_stairs);
        world.setBlock(i + 6, j + 5, k + 7, ProjectFruitRegistry.lemonBrick);
        world.setBlock(i + 6, j + 6, k + 0, ProjectFruitRegistry.lemonBrick);
        world.setBlock(i + 6, j + 6, k + 1, Blocks.oak_stairs);
        world.setBlock(i + 6, j + 6, k + 2, Blocks.air);
        world.setBlock(i + 6, j + 6, k + 3, Blocks.air);
        world.setBlock(i + 6, j + 6, k + 4, Blocks.air);
        world.setBlock(i + 6, j + 6, k + 5, Blocks.air);
        world.setBlock(i + 6, j + 6, k + 6, Blocks.oak_stairs);
        world.setBlock(i + 6, j + 6, k + 7, ProjectFruitRegistry.lemonBrick);
        world.setBlock(i + 6, j + 7, k + 0, ProjectFruitRegistry.lemonBrick);
        world.setBlock(i + 6, j + 7, k + 1, Blocks.air);
        world.setBlock(i + 6, j + 7, k + 2, Blocks.air);
        world.setBlock(i + 6, j + 7, k + 3, Blocks.air);
        world.setBlock(i + 6, j + 7, k + 4, Blocks.air);
        world.setBlock(i + 6, j + 7, k + 5, Blocks.air);
        world.setBlock(i + 6, j + 7, k + 6, Blocks.air);
        world.setBlock(i + 6, j + 7, k + 7, ProjectFruitRegistry.lemonBrick);
        world.setBlock(i + 6, j + 8, k + 0, Blocks.air);
        world.setBlock(i + 6, j + 8, k + 1, ProjectFruitRegistry.lemonBrick);
        world.setBlock(i + 6, j + 8, k + 2, ProjectFruitRegistry.lemonBrick);
        world.setBlock(i + 6, j + 8, k + 3, Blocks.glass);
        world.setBlock(i + 6, j + 8, k + 4, Blocks.glass);
        world.setBlock(i + 6, j + 8, k + 5, ProjectFruitRegistry.lemonBrick);
        world.setBlock(i + 6, j + 8, k + 6, ProjectFruitRegistry.lemonBrick);
        world.setBlock(i + 6, j + 8, k + 7, Blocks.air);
        world.setBlock(i + 7, j + 0, k + 0, ProjectFruitRegistry.lemonBrick);
        world.setBlock(i + 7, j + 0, k + 1, Blocks.planks);
        world.setBlock(i + 7, j + 0, k + 2, Blocks.planks);
        world.setBlock(i + 7, j + 0, k + 3, Blocks.planks);
        world.setBlock(i + 7, j + 0, k + 4, Blocks.planks);
        world.setBlock(i + 7, j + 0, k + 5, Blocks.planks);
        world.setBlock(i + 7, j + 0, k + 6, Blocks.planks);
        world.setBlock(i + 7, j + 0, k + 7, ProjectFruitRegistry.lemonBrick);
        world.setBlock(i + 7, j + 1, k + 0, ProjectFruitRegistry.lemonBrick);
        world.setBlock(i + 7, j + 1, k + 1, Blocks.air);
        world.setBlock(i + 7, j + 1, k + 2, Blocks.air);
        world.setBlock(i + 7, j + 1, k + 3, Blocks.planks);
        world.setBlock(i + 7, j + 1, k + 4, Blocks.planks);
        world.setBlock(i + 7, j + 1, k + 5, Blocks.air);
        world.setBlock(i + 7, j + 1, k + 6, Blocks.air);
        world.setBlock(i + 7, j + 1, k + 7, ProjectFruitRegistry.lemonBrick);
        world.setBlock(i + 7, j + 2, k + 0, ProjectFruitRegistry.lemonBrick);
        world.setBlock(i + 7, j + 2, k + 1, Blocks.air);
        world.setBlock(i + 7, j + 2, k + 2, Blocks.air);
        world.setBlock(i + 7, j + 2, k + 3, Blocks.oak_stairs);
        world.setBlock(i + 7, j + 2, k + 4, Blocks.oak_stairs);
        world.setBlock(i + 7, j + 2, k + 5, Blocks.air);
        world.setBlock(i + 7, j + 2, k + 6, Blocks.air);
        world.setBlock(i + 7, j + 2, k + 7, Blocks.glass_pane);
        world.setBlock(i + 7, j + 3, k + 0, ProjectFruitRegistry.lemonBrick);
        world.setBlock(i + 7, j + 3, k + 1, Blocks.air);
        world.setBlock(i + 7, j + 3, k + 2, Blocks.air);
        world.setBlock(i + 7, j + 3, k + 3, Blocks.air);
        world.setBlock(i + 7, j + 3, k + 4, Blocks.air);
        world.setBlock(i + 7, j + 3, k + 5, Blocks.air);
        world.setBlock(i + 7, j + 3, k + 6, Blocks.air);
        world.setBlock(i + 7, j + 3, k + 7, ProjectFruitRegistry.lemonBrick);
        world.setBlock(i + 7, j + 4, k + 0, ProjectFruitRegistry.lemonBrick);
        world.setBlock(i + 7, j + 4, k + 1, Blocks.planks);
        world.setBlock(i + 7, j + 4, k + 2, Blocks.planks);
        world.setBlock(i + 7, j + 4, k + 3, Blocks.air);
        world.setBlock(i + 7, j + 4, k + 4, Blocks.air);
        world.setBlock(i + 7, j + 4, k + 5, Blocks.planks);
        world.setBlock(i + 7, j + 4, k + 6, Blocks.planks);
        world.setBlock(i + 7, j + 4, k + 7, ProjectFruitRegistry.lemonBrick);
        world.setBlock(i + 7, j + 5, k + 0, ProjectFruitRegistry.lemonBrick);
        world.setBlock(i + 7, j + 5, k + 1, Blocks.wooden_slab);
        world.setBlock(i + 7, j + 5, k + 2, Blocks.air);
        world.setBlock(i + 7, j + 5, k + 3, Blocks.air);
        world.setBlock(i + 7, j + 5, k + 4, Blocks.air);
        world.setBlock(i + 7, j + 5, k + 5, Blocks.air);
        world.setBlock(i + 7, j + 5, k + 6, Blocks.wooden_slab);
        world.setBlock(i + 7, j + 5, k + 7, ProjectFruitRegistry.lemonBrick);
        world.setBlock(i + 7, j + 6, k + 0, ProjectFruitRegistry.lemonBrick);
        world.setBlock(i + 7, j + 6, k + 1, Blocks.wooden_slab);
        world.setBlock(i + 7, j + 6, k + 2, Blocks.air);
        world.setBlock(i + 7, j + 6, k + 3, Blocks.air);
        world.setBlock(i + 7, j + 6, k + 4, Blocks.air);
        world.setBlock(i + 7, j + 6, k + 5, Blocks.air);
        world.setBlock(i + 7, j + 6, k + 6, Blocks.wooden_slab);
        world.setBlock(i + 7, j + 6, k + 7, ProjectFruitRegistry.lemonBrick);
        world.setBlock(i + 7, j + 7, k + 0, ProjectFruitRegistry.lemonBrick);
        world.setBlock(i + 7, j + 7, k + 1, Blocks.air);
        world.setBlock(i + 7, j + 7, k + 2, Blocks.air);
        world.setBlock(i + 7, j + 7, k + 3, Blocks.air);
        world.setBlock(i + 7, j + 7, k + 4, Blocks.air);
        world.setBlock(i + 7, j + 7, k + 5, Blocks.air);
        world.setBlock(i + 7, j + 7, k + 6, Blocks.air);
        world.setBlock(i + 7, j + 7, k + 7, ProjectFruitRegistry.lemonBrick);
        world.setBlock(i + 7, j + 8, k + 0, Blocks.air);
        world.setBlock(i + 7, j + 8, k + 1, ProjectFruitRegistry.lemonBrick);
        world.setBlock(i + 7, j + 8, k + 2, Blocks.glass);
        world.setBlock(i + 7, j + 8, k + 3, Blocks.glass);
        world.setBlock(i + 7, j + 8, k + 4, Blocks.glass);
        world.setBlock(i + 7, j + 8, k + 5, Blocks.glass);
        world.setBlock(i + 7, j + 8, k + 6, ProjectFruitRegistry.lemonBrick);
        world.setBlock(i + 7, j + 8, k + 7, Blocks.air);
        world.setBlock(i + 8, j + 0, k + 0, ProjectFruitRegistry.lemonBrick);
        world.setBlock(i + 8, j + 0, k + 1, Blocks.planks);
        world.setBlock(i + 8, j + 0, k + 2, Blocks.planks);
        world.setBlock(i + 8, j + 0, k + 3, Blocks.planks);
        world.setBlock(i + 8, j + 0, k + 4, Blocks.planks);
        world.setBlock(i + 8, j + 0, k + 5, Blocks.planks);
        world.setBlock(i + 8, j + 0, k + 6, Blocks.planks);
        world.setBlock(i + 8, j + 0, k + 7, ProjectFruitRegistry.lemonBrick);
        world.setBlock(i + 8, j + 1, k + 0, ProjectFruitRegistry.lemonBrick);
        world.setBlock(i + 8, j + 1, k + 1, Blocks.air);
        world.setBlock(i + 8, j + 1, k + 2, Blocks.air);
        world.setBlock(i + 8, j + 1, k + 3, Blocks.planks);
        world.setBlock(i + 8, j + 1, k + 4, Blocks.planks);
        world.setBlock(i + 8, j + 1, k + 5, Blocks.air);
        world.setBlock(i + 8, j + 1, k + 6, Blocks.air);
        world.setBlock(i + 8, j + 1, k + 7, ProjectFruitRegistry.lemonBrick);
        world.setBlock(i + 8, j + 2, k + 0, ProjectFruitRegistry.lemonBrick);
        world.setBlock(i + 8, j + 2, k + 1, Blocks.air);
        world.setBlock(i + 8, j + 2, k + 2, Blocks.air);
        world.setBlock(i + 8, j + 2, k + 3, Blocks.planks);
        world.setBlock(i + 8, j + 2, k + 4, Blocks.planks);
        world.setBlock(i + 8, j + 2, k + 5, Blocks.air);
        world.setBlock(i + 8, j + 2, k + 6, Blocks.air);
        world.setBlock(i + 8, j + 2, k + 7, Blocks.glass_pane);
        world.setBlock(i + 8, j + 3, k + 0, ProjectFruitRegistry.lemonBrick);
        world.setBlock(i + 8, j + 3, k + 1, Blocks.air);
        world.setBlock(i + 8, j + 3, k + 2, Blocks.air);
        world.setBlock(i + 8, j + 3, k + 3, Blocks.oak_stairs);
        world.setBlock(i + 8, j + 3, k + 4, Blocks.oak_stairs);
        world.setBlock(i + 8, j + 3, k + 5, Blocks.air);
        world.setBlock(i + 8, j + 3, k + 6, Blocks.air);
        world.setBlock(i + 8, j + 3, k + 7, ProjectFruitRegistry.lemonBrick);
        world.setBlock(i + 8, j + 4, k + 0, ProjectFruitRegistry.lemonBrick);
        world.setBlock(i + 8, j + 4, k + 1, Blocks.planks);
        world.setBlock(i + 8, j + 4, k + 2, Blocks.planks);
        world.setBlock(i + 8, j + 4, k + 3, Blocks.air);
        world.setBlock(i + 8, j + 4, k + 4, Blocks.air);
        world.setBlock(i + 8, j + 4, k + 5, Blocks.planks);
        world.setBlock(i + 8, j + 4, k + 6, Blocks.planks);
        world.setBlock(i + 8, j + 4, k + 7, ProjectFruitRegistry.lemonBrick);
        world.setBlock(i + 8, j + 5, k + 0, ProjectFruitRegistry.lemonBrick);
        world.setBlock(i + 8, j + 5, k + 1, Blocks.wooden_slab);
        world.setBlock(i + 8, j + 5, k + 2, Blocks.air);
        world.setBlock(i + 8, j + 5, k + 3, Blocks.air);
        world.setBlock(i + 8, j + 5, k + 4, Blocks.air);
        world.setBlock(i + 8, j + 5, k + 5, Blocks.air);
        world.setBlock(i + 8, j + 5, k + 6, Blocks.wooden_slab);
        world.setBlock(i + 8, j + 5, k + 7, ProjectFruitRegistry.lemonBrick);
        world.setBlock(i + 8, j + 6, k + 0, ProjectFruitRegistry.lemonBrick);
        world.setBlock(i + 8, j + 6, k + 1, Blocks.wooden_slab);
        world.setBlock(i + 8, j + 6, k + 2, Blocks.air);
        world.setBlock(i + 8, j + 6, k + 3, Blocks.air);
        world.setBlock(i + 8, j + 6, k + 4, Blocks.air);
        world.setBlock(i + 8, j + 6, k + 5, Blocks.air);
        world.setBlock(i + 8, j + 6, k + 6, Blocks.wooden_slab);
        world.setBlock(i + 8, j + 6, k + 7, ProjectFruitRegistry.lemonBrick);
        world.setBlock(i + 8, j + 7, k + 0, ProjectFruitRegistry.lemonBrick);
        world.setBlock(i + 8, j + 7, k + 1, Blocks.air);
        world.setBlock(i + 8, j + 7, k + 2, Blocks.air);
        world.setBlock(i + 8, j + 7, k + 3, Blocks.air);
        world.setBlock(i + 8, j + 7, k + 4, Blocks.air);
        world.setBlock(i + 8, j + 7, k + 5, Blocks.air);
        world.setBlock(i + 8, j + 7, k + 6, Blocks.air);
        world.setBlock(i + 8, j + 7, k + 7, ProjectFruitRegistry.lemonBrick);
        world.setBlock(i + 8, j + 8, k + 0, Blocks.air);
        world.setBlock(i + 8, j + 8, k + 1, ProjectFruitRegistry.lemonBrick);
        world.setBlock(i + 8, j + 8, k + 2, Blocks.glass);
        world.setBlock(i + 8, j + 8, k + 3, Blocks.glass);
        world.setBlock(i + 8, j + 8, k + 4, Blocks.glass);
        world.setBlock(i + 8, j + 8, k + 5, Blocks.glass);
        world.setBlock(i + 8, j + 8, k + 6, ProjectFruitRegistry.lemonBrick);
        world.setBlock(i + 8, j + 8, k + 7, Blocks.air);
        world.setBlock(i + 9, j + 0, k + 0, ProjectFruitRegistry.lemonBrick);
        world.setBlock(i + 9, j + 0, k + 1, Blocks.planks);
        world.setBlock(i + 9, j + 0, k + 2, Blocks.planks);
        world.setBlock(i + 9, j + 0, k + 3, Blocks.planks);
        world.setBlock(i + 9, j + 0, k + 4, Blocks.planks);
        world.setBlock(i + 9, j + 0, k + 5, Blocks.planks);
        world.setBlock(i + 9, j + 0, k + 6, Blocks.planks);
        world.setBlock(i + 9, j + 0, k + 7, ProjectFruitRegistry.lemonBrick);
        world.setBlock(i + 9, j + 1, k + 0, ProjectFruitRegistry.lemonBrick);
        world.setBlock(i + 9, j + 1, k + 1, Blocks.air);
        world.setBlock(i + 9, j + 1, k + 2, Blocks.air);
        world.setBlock(i + 9, j + 1, k + 3, Blocks.air);
        world.setBlock(i + 9, j + 1, k + 4, Blocks.air);
        world.setBlock(i + 9, j + 1, k + 5, Blocks.air);
        world.setBlock(i + 9, j + 1, k + 6, Blocks.air);
        world.setBlock(i + 9, j + 1, k + 7, ProjectFruitRegistry.lemonBrick);
        world.setBlock(i + 9, j + 2, k + 0, ProjectFruitRegistry.lemonBrick);
        world.setBlock(i + 9, j + 2, k + 1, Blocks.air);
        world.setBlock(i + 9, j + 2, k + 2, Blocks.air);
        world.setBlock(i + 9, j + 2, k + 3, Blocks.air);
        world.setBlock(i + 9, j + 2, k + 4, Blocks.air);
        world.setBlock(i + 9, j + 2, k + 5, Blocks.air);
        world.setBlock(i + 9, j + 2, k + 6, Blocks.air);
        world.setBlock(i + 9, j + 2, k + 7, ProjectFruitRegistry.lemonBrick);
        world.setBlock(i + 9, j + 3, k + 0, ProjectFruitRegistry.lemonBrick);
        world.setBlock(i + 9, j + 3, k + 1, Blocks.air);
        world.setBlock(i + 9, j + 3, k + 2, Blocks.air);
        world.setBlock(i + 9, j + 3, k + 3, Blocks.air);
        world.setBlock(i + 9, j + 3, k + 4, Blocks.air);
        world.setBlock(i + 9, j + 3, k + 5, Blocks.air);
        world.setBlock(i + 9, j + 3, k + 6, Blocks.air);
        world.setBlock(i + 9, j + 3, k + 7, ProjectFruitRegistry.lemonBrick);
        world.setBlock(i + 9, j + 4, k + 0, ProjectFruitRegistry.lemonBrick);
        world.setBlock(i + 9, j + 4, k + 1, Blocks.planks);
        world.setBlock(i + 9, j + 4, k + 2, Blocks.planks);
        world.setBlock(i + 9, j + 4, k + 3, Blocks.oak_stairs);
        world.setBlock(i + 9, j + 4, k + 4, Blocks.oak_stairs);
        world.setBlock(i + 9, j + 4, k + 5, Blocks.planks);
        world.setBlock(i + 9, j + 4, k + 6, Blocks.planks);
        world.setBlock(i + 9, j + 4, k + 7, ProjectFruitRegistry.lemonBrick);
        world.setBlock(i + 9, j + 5, k + 0, ProjectFruitRegistry.lemonBrick);
        world.setBlock(i + 9, j + 5, k + 1, Blocks.wooden_slab);
        world.setBlock(i + 9, j + 5, k + 2, Blocks.air);
        world.setBlock(i + 9, j + 5, k + 3, Blocks.air);
        world.setBlock(i + 9, j + 5, k + 4, Blocks.air);
        world.setBlock(i + 9, j + 5, k + 5, Blocks.air);
        world.setBlock(i + 9, j + 5, k + 6, Blocks.wooden_slab);
        world.setBlock(i + 9, j + 5, k + 7, ProjectFruitRegistry.lemonBrick);
        world.setBlock(i + 9, j + 6, k + 0, ProjectFruitRegistry.lemonBrick);
        world.setBlock(i + 9, j + 6, k + 1, Blocks.wooden_slab);
        world.setBlock(i + 9, j + 6, k + 2, Blocks.air);
        world.setBlock(i + 9, j + 6, k + 3, Blocks.air);
        world.setBlock(i + 9, j + 6, k + 4, Blocks.air);
        world.setBlock(i + 9, j + 6, k + 5, Blocks.air);
        world.setBlock(i + 9, j + 6, k + 6, Blocks.wooden_slab);
        world.setBlock(i + 9, j + 6, k + 7, ProjectFruitRegistry.lemonBrick);
        world.setBlock(i + 9, j + 7, k + 0, ProjectFruitRegistry.lemonBrick);
        world.setBlock(i + 9, j + 7, k + 1, Blocks.air);
        world.setBlock(i + 9, j + 7, k + 2, Blocks.air);
        world.setBlock(i + 9, j + 7, k + 3, Blocks.air);
        world.setBlock(i + 9, j + 7, k + 4, Blocks.air);
        world.setBlock(i + 9, j + 7, k + 5, Blocks.air);
        world.setBlock(i + 9, j + 7, k + 6, Blocks.air);
        world.setBlock(i + 9, j + 7, k + 7, ProjectFruitRegistry.lemonBrick);
        world.setBlock(i + 9, j + 8, k + 0, Blocks.air);
        world.setBlock(i + 9, j + 8, k + 1, ProjectFruitRegistry.lemonBrick);
        world.setBlock(i + 9, j + 8, k + 2, Blocks.glass);
        world.setBlock(i + 9, j + 8, k + 3, Blocks.glass);
        world.setBlock(i + 9, j + 8, k + 4, Blocks.glass);
        world.setBlock(i + 9, j + 8, k + 5, Blocks.glass);
        world.setBlock(i + 9, j + 8, k + 6, ProjectFruitRegistry.lemonBrick);
        world.setBlock(i + 9, j + 8, k + 7, Blocks.air);
        world.setBlock(i + 10, j + 0, k + 0, ProjectFruitRegistry.lemonBrick);
        world.setBlock(i + 10, j + 0, k + 1, Blocks.planks);
        world.setBlock(i + 10, j + 0, k + 2, Blocks.planks);
        world.setBlock(i + 10, j + 0, k + 3, Blocks.planks);
        world.setBlock(i + 10, j + 0, k + 4, Blocks.planks);
        world.setBlock(i + 10, j + 0, k + 5, Blocks.planks);
        world.setBlock(i + 10, j + 0, k + 6, Blocks.planks);
        world.setBlock(i + 10, j + 0, k + 7, Blocks.planks);
        world.setBlock(i + 10, j + 1, k + 0, ProjectFruitRegistry.lemonBrick);
        world.setBlock(i + 10, j + 1, k + 1, Blocks.air);
        world.setBlock(i + 10, j + 1, k + 2, Blocks.air);
        world.setBlock(i + 10, j + 1, k + 3, Blocks.air);
        world.setBlock(i + 10, j + 1, k + 4, Blocks.air);
        world.setBlock(i + 10, j + 1, k + 5, Blocks.air);
        world.setBlock(i + 10, j + 1, k + 6, Blocks.air);
        world.setBlock(i + 10, j + 2, k + 0, ProjectFruitRegistry.lemonBrick);
        world.setBlock(i + 10, j + 2, k + 1, Blocks.air);
        world.setBlock(i + 10, j + 2, k + 2, Blocks.air);
        world.setBlock(i + 10, j + 2, k + 3, Blocks.air);
        world.setBlock(i + 10, j + 2, k + 4, Blocks.air);
        world.setBlock(i + 10, j + 2, k + 5, Blocks.air);
        world.setBlock(i + 10, j + 2, k + 6, Blocks.air);
        world.setBlock(i + 10, j + 3, k + 0, ProjectFruitRegistry.lemonBrick);
        world.setBlock(i + 10, j + 3, k + 1, Blocks.air);
        world.setBlock(i + 10, j + 3, k + 2, Blocks.air);
        world.setBlock(i + 10, j + 3, k + 3, Blocks.air);
        world.setBlock(i + 10, j + 3, k + 4, Blocks.air);
        world.setBlock(i + 10, j + 3, k + 5, Blocks.air);
        world.setBlock(i + 10, j + 3, k + 6, Blocks.air);
        world.setBlock(i + 10, j + 3, k + 7, Blocks.glowstone);
        world.setBlock(i + 10, j + 4, k + 0, ProjectFruitRegistry.lemonBrick);
        world.setBlock(i + 10, j + 4, k + 1, Blocks.planks);
        world.setBlock(i + 10, j + 4, k + 2, Blocks.planks);
        world.setBlock(i + 10, j + 4, k + 3, Blocks.planks);
        world.setBlock(i + 10, j + 4, k + 4, Blocks.planks);
        world.setBlock(i + 10, j + 4, k + 5, Blocks.planks);
        world.setBlock(i + 10, j + 4, k + 6, Blocks.planks);
        world.setBlock(i + 10, j + 4, k + 7, ProjectFruitRegistry.lemonBrick);
        world.setBlock(i + 10, j + 5, k + 0, ProjectFruitRegistry.lemonBrick);
        world.setBlock(i + 10, j + 5, k + 1, Blocks.wooden_slab);
        world.setBlock(i + 10, j + 5, k + 2, Blocks.air);
        world.setBlock(i + 10, j + 5, k + 3, Blocks.air);
        world.setBlock(i + 10, j + 5, k + 4, Blocks.air);
        world.setBlock(i + 10, j + 5, k + 5, Blocks.air);
        world.setBlock(i + 10, j + 5, k + 6, Blocks.wooden_slab);
        world.setBlock(i + 10, j + 5, k + 7, ProjectFruitRegistry.lemonBrick);
        world.setBlock(i + 10, j + 6, k + 0, ProjectFruitRegistry.lemonBrick);
        world.setBlock(i + 10, j + 6, k + 1, Blocks.wooden_slab);
        world.setBlock(i + 10, j + 6, k + 2, Blocks.air);
        world.setBlock(i + 10, j + 6, k + 3, Blocks.air);
        world.setBlock(i + 10, j + 6, k + 4, Blocks.air);
        world.setBlock(i + 10, j + 6, k + 5, Blocks.air);
        world.setBlock(i + 10, j + 6, k + 6, Blocks.wooden_slab);
        world.setBlock(i + 10, j + 6, k + 7, ProjectFruitRegistry.lemonBrick);
        world.setBlock(i + 10, j + 7, k + 0, ProjectFruitRegistry.lemonBrick);
        world.setBlock(i + 10, j + 7, k + 1, Blocks.air);
        world.setBlock(i + 10, j + 7, k + 2, Blocks.air);
        world.setBlock(i + 10, j + 7, k + 3, Blocks.air);
        world.setBlock(i + 10, j + 7, k + 4, Blocks.air);
        world.setBlock(i + 10, j + 7, k + 5, Blocks.air);
        world.setBlock(i + 10, j + 7, k + 6, Blocks.air);
        world.setBlock(i + 10, j + 7, k + 7, ProjectFruitRegistry.lemonBrick);
        world.setBlock(i + 10, j + 8, k + 0, Blocks.air);
        world.setBlock(i + 10, j + 8, k + 1, ProjectFruitRegistry.lemonBrick);
        world.setBlock(i + 10, j + 8, k + 2, Blocks.glass);
        world.setBlock(i + 10, j + 8, k + 3, Blocks.glass);
        world.setBlock(i + 10, j + 8, k + 4, Blocks.glass);
        world.setBlock(i + 10, j + 8, k + 5, Blocks.glass);
        world.setBlock(i + 10, j + 8, k + 6, ProjectFruitRegistry.lemonBrick);
        world.setBlock(i + 10, j + 8, k + 7, Blocks.air);
        world.setBlock(i + 11, j + 0, k + 0, ProjectFruitRegistry.lemonBrick);
        world.setBlock(i + 11, j + 0, k + 1, Blocks.planks);
        world.setBlock(i + 11, j + 0, k + 2, Blocks.planks);
        world.setBlock(i + 11, j + 0, k + 3, Blocks.planks);
        world.setBlock(i + 11, j + 0, k + 4, Blocks.planks);
        world.setBlock(i + 11, j + 0, k + 5, Blocks.planks);
        world.setBlock(i + 11, j + 0, k + 6, Blocks.planks);
        world.setBlock(i + 11, j + 0, k + 7, ProjectFruitRegistry.lemonBrick);
        world.setBlock(i + 11, j + 1, k + 0, ProjectFruitRegistry.lemonBrick);
        world.setBlock(i + 11, j + 1, k + 1, Blocks.log);
        world.setBlock(i + 11, j + 1, k + 2, Blocks.air);
        world.setBlock(i + 11, j + 1, k + 3, Blocks.air);
        world.setBlock(i + 11, j + 1, k + 4, Blocks.air);
        world.setBlock(i + 11, j + 1, k + 5, Blocks.air);
        world.setBlock(i + 11, j + 1, k + 6, Blocks.air);
        world.setBlock(i + 11, j + 1, k + 7, ProjectFruitRegistry.lemonBrick);
        world.setBlock(i + 11, j + 2, k + 0, ProjectFruitRegistry.lemonBrick);
        world.setBlock(i + 11, j + 2, k + 1, Blocks.glowstone);
        world.setBlock(i + 11, j + 2, k + 2, Blocks.air);
        world.setBlock(i + 11, j + 2, k + 3, Blocks.air);
        world.setBlock(i + 11, j + 2, k + 4, Blocks.air);
        world.setBlock(i + 11, j + 2, k + 5, Blocks.air);
        world.setBlock(i + 11, j + 2, k + 6, Blocks.air);
        world.setBlock(i + 11, j + 2, k + 7, ProjectFruitRegistry.lemonBrick);
        world.setBlock(i + 11, j + 3, k + 0, ProjectFruitRegistry.lemonBrick);
        world.setBlock(i + 11, j + 3, k + 1, Blocks.bookshelf);
        world.setBlock(i + 11, j + 3, k + 2, Blocks.air);
        world.setBlock(i + 11, j + 3, k + 3, Blocks.air);
        world.setBlock(i + 11, j + 3, k + 4, Blocks.air);
        world.setBlock(i + 11, j + 3, k + 5, Blocks.air);
        world.setBlock(i + 11, j + 3, k + 6, Blocks.air);
        world.setBlock(i + 11, j + 3, k + 7, ProjectFruitRegistry.lemonBrick);
        world.setBlock(i + 11, j + 4, k + 0, ProjectFruitRegistry.lemonBrick);
        world.setBlock(i + 11, j + 4, k + 1, Blocks.planks);
        world.setBlock(i + 11, j + 4, k + 2, Blocks.planks);
        world.setBlock(i + 11, j + 4, k + 3, Blocks.planks);
        world.setBlock(i + 11, j + 4, k + 4, Blocks.planks);
        world.setBlock(i + 11, j + 4, k + 5, Blocks.planks);
        world.setBlock(i + 11, j + 4, k + 6, Blocks.planks);
        world.setBlock(i + 11, j + 4, k + 7, ProjectFruitRegistry.lemonBrick);
        world.setBlock(i + 11, j + 5, k + 0, ProjectFruitRegistry.lemonBrick);
        world.setBlock(i + 11, j + 5, k + 1, Blocks.wooden_slab);
        world.setBlock(i + 11, j + 5, k + 2, Blocks.air);
        world.setBlock(i + 11, j + 5, k + 3, Blocks.air);
        world.setBlock(i + 11, j + 5, k + 4, Blocks.air);
        world.setBlock(i + 11, j + 5, k + 5, Blocks.air);
        world.setBlock(i + 11, j + 5, k + 6, Blocks.wooden_slab);
        world.setBlock(i + 11, j + 5, k + 7, ProjectFruitRegistry.lemonBrick);
        world.setBlock(i + 11, j + 6, k + 0, ProjectFruitRegistry.lemonBrick);
        world.setBlock(i + 11, j + 6, k + 1, Blocks.wooden_slab);
        world.setBlock(i + 11, j + 6, k + 2, Blocks.air);
        world.setBlock(i + 11, j + 6, k + 3, Blocks.air);
        world.setBlock(i + 11, j + 6, k + 4, Blocks.air);
        world.setBlock(i + 11, j + 6, k + 5, Blocks.air);
        world.setBlock(i + 11, j + 6, k + 6, Blocks.wooden_slab);
        world.setBlock(i + 11, j + 6, k + 7, ProjectFruitRegistry.lemonBrick);
        world.setBlock(i + 11, j + 7, k + 0, ProjectFruitRegistry.lemonBrick);
        world.setBlock(i + 11, j + 7, k + 1, Blocks.air);
        world.setBlock(i + 11, j + 7, k + 2, Blocks.air);
        world.setBlock(i + 11, j + 7, k + 3, Blocks.air);
        world.setBlock(i + 11, j + 7, k + 4, Blocks.air);
        world.setBlock(i + 11, j + 7, k + 5, Blocks.air);
        world.setBlock(i + 11, j + 7, k + 6, Blocks.air);
        world.setBlock(i + 11, j + 7, k + 7, ProjectFruitRegistry.lemonBrick);
        world.setBlock(i + 11, j + 8, k + 0, Blocks.air);
        world.setBlock(i + 11, j + 8, k + 1, ProjectFruitRegistry.lemonBrick);
        world.setBlock(i + 11, j + 8, k + 2, Blocks.glass);
        world.setBlock(i + 11, j + 8, k + 3, Blocks.glass);
        world.setBlock(i + 11, j + 8, k + 4, Blocks.glass);
        world.setBlock(i + 11, j + 8, k + 5, Blocks.glass);
        world.setBlock(i + 11, j + 8, k + 6, ProjectFruitRegistry.lemonBrick);
        world.setBlock(i + 11, j + 8, k + 7, Blocks.air);
        world.setBlock(i + 12, j + 0, k + 0, ProjectFruitRegistry.lemonBrick);
        world.setBlock(i + 12, j + 0, k + 1, Blocks.planks);
        world.setBlock(i + 12, j + 0, k + 2, Blocks.planks);
        world.setBlock(i + 12, j + 0, k + 3, Blocks.planks);
        world.setBlock(i + 12, j + 0, k + 4, Blocks.planks);
        world.setBlock(i + 12, j + 0, k + 5, Blocks.planks);
        world.setBlock(i + 12, j + 0, k + 6, Blocks.planks);
        world.setBlock(i + 12, j + 0, k + 7, ProjectFruitRegistry.lemonBrick);
        world.setBlock(i + 12, j + 1, k + 0, ProjectFruitRegistry.lemonBrick);
        world.setBlock(i + 12, j + 1, k + 1, Blocks.log);
        world.setBlock(i + 12, j + 1, k + 2, Blocks.air);
        world.setBlock(i + 12, j + 1, k + 3, Blocks.air);
        world.setBlock(i + 12, j + 1, k + 4, Blocks.air);
        world.setBlock(i + 12, j + 1, k + 5, Blocks.air);
        world.setBlock(i + 12, j + 1, k + 6, Blocks.air);
        world.setBlock(i + 12, j + 1, k + 7, ProjectFruitRegistry.lemonBrick);
        world.setBlock(i + 12, j + 2, k + 0, ProjectFruitRegistry.lemonBrick);
        world.setBlock(i + 12, j + 2, k + 1, Blocks.air);
        world.setBlock(i + 12, j + 2, k + 2, Blocks.air);
        world.setBlock(i + 12, j + 2, k + 3, Blocks.air);
        world.setBlock(i + 12, j + 2, k + 4, Blocks.air);
        world.setBlock(i + 12, j + 2, k + 5, Blocks.air);
        world.setBlock(i + 12, j + 2, k + 6, Blocks.air);
        world.setBlock(i + 12, j + 2, k + 7, Blocks.glass_pane);
        world.setBlock(i + 12, j + 3, k + 0, ProjectFruitRegistry.lemonBrick);
        world.setBlock(i + 12, j + 3, k + 1, Blocks.bookshelf);
        world.setBlock(i + 12, j + 3, k + 2, Blocks.air);
        world.setBlock(i + 12, j + 3, k + 3, Blocks.air);
        world.setBlock(i + 12, j + 3, k + 4, Blocks.air);
        world.setBlock(i + 12, j + 3, k + 5, Blocks.air);
        world.setBlock(i + 12, j + 3, k + 6, Blocks.air);
        world.setBlock(i + 12, j + 3, k + 7, ProjectFruitRegistry.lemonBrick);
        world.setBlock(i + 12, j + 4, k + 0, ProjectFruitRegistry.lemonBrick);
        world.setBlock(i + 12, j + 4, k + 1, Blocks.planks);
        world.setBlock(i + 12, j + 4, k + 2, Blocks.planks);
        world.setBlock(i + 12, j + 4, k + 3, Blocks.planks);
        world.setBlock(i + 12, j + 4, k + 4, Blocks.planks);
        world.setBlock(i + 12, j + 4, k + 5, Blocks.planks);
        world.setBlock(i + 12, j + 4, k + 6, Blocks.planks);
        world.setBlock(i + 12, j + 4, k + 7, ProjectFruitRegistry.lemonBrick);
        world.setBlock(i + 12, j + 5, k + 0, ProjectFruitRegistry.lemonBrick);
        world.setBlock(i + 12, j + 5, k + 1, Blocks.wooden_slab);
        world.setBlock(i + 12, j + 5, k + 2, Blocks.air);
        world.setBlock(i + 12, j + 5, k + 3, Blocks.air);
        world.setBlock(i + 12, j + 5, k + 4, Blocks.air);
        world.setBlock(i + 12, j + 5, k + 5, Blocks.air);
        world.setBlock(i + 12, j + 5, k + 6, Blocks.wooden_slab);
        world.setBlock(i + 12, j + 5, k + 7, ProjectFruitRegistry.lemonBrick);
        world.setBlock(i + 12, j + 6, k + 0, ProjectFruitRegistry.lemonBrick);
        world.setBlock(i + 12, j + 6, k + 1, Blocks.wooden_slab);
        world.setBlock(i + 12, j + 6, k + 2, Blocks.air);
        world.setBlock(i + 12, j + 6, k + 3, Blocks.air);
        world.setBlock(i + 12, j + 6, k + 4, Blocks.air);
        world.setBlock(i + 12, j + 6, k + 5, Blocks.air);
        world.setBlock(i + 12, j + 6, k + 6, Blocks.wooden_slab);
        world.setBlock(i + 12, j + 6, k + 7, ProjectFruitRegistry.lemonBrick);
        world.setBlock(i + 12, j + 7, k + 0, ProjectFruitRegistry.lemonBrick);
        world.setBlock(i + 12, j + 7, k + 1, Blocks.air);
        world.setBlock(i + 12, j + 7, k + 2, Blocks.air);
        world.setBlock(i + 12, j + 7, k + 3, Blocks.air);
        world.setBlock(i + 12, j + 7, k + 4, Blocks.air);
        world.setBlock(i + 12, j + 7, k + 5, Blocks.air);
        world.setBlock(i + 12, j + 7, k + 6, Blocks.air);
        world.setBlock(i + 12, j + 7, k + 7, ProjectFruitRegistry.lemonBrick);
        world.setBlock(i + 12, j + 8, k + 0, Blocks.air);
        world.setBlock(i + 12, j + 8, k + 1, ProjectFruitRegistry.lemonBrick);
        world.setBlock(i + 12, j + 8, k + 2, Blocks.glass);
        world.setBlock(i + 12, j + 8, k + 3, Blocks.glass);
        world.setBlock(i + 12, j + 8, k + 4, Blocks.glass);
        world.setBlock(i + 12, j + 8, k + 5, Blocks.glass);
        world.setBlock(i + 12, j + 8, k + 6, ProjectFruitRegistry.lemonBrick);
        world.setBlock(i + 12, j + 8, k + 7, Blocks.air);
        world.setBlock(i + 13, j + 0, k + 0, ProjectFruitRegistry.lemonBrick);
        world.setBlock(i + 13, j + 0, k + 1, Blocks.planks);
        world.setBlock(i + 13, j + 0, k + 2, Blocks.planks);
        world.setBlock(i + 13, j + 0, k + 3, Blocks.planks);
        world.setBlock(i + 13, j + 0, k + 4, Blocks.planks);
        world.setBlock(i + 13, j + 0, k + 5, Blocks.planks);
        world.setBlock(i + 13, j + 0, k + 6, Blocks.planks);
        world.setBlock(i + 13, j + 0, k + 7, ProjectFruitRegistry.lemonBrick);
        world.setBlock(i + 13, j + 1, k + 0, ProjectFruitRegistry.lemonBrick);
        world.setBlock(i + 13, j + 1, k + 1, Blocks.cauldron);
        world.setBlock(i + 13, j + 1, k + 2, Blocks.air);
        world.setBlock(i + 13, j + 1, k + 3, Blocks.air);
        world.setBlock(i + 13, j + 1, k + 4, Blocks.air);
        world.setBlock(i + 13, j + 1, k + 5, Blocks.air);
        world.setBlock(i + 13, j + 1, k + 6, Blocks.air);
        world.setBlock(i + 13, j + 1, k + 7, ProjectFruitRegistry.lemonBrick);
        world.setBlock(i + 13, j + 2, k + 0, ProjectFruitRegistry.lemonBrick);
        world.setBlock(i + 13, j + 2, k + 1, Blocks.air);
        world.setBlock(i + 13, j + 2, k + 2, Blocks.air);
        world.setBlock(i + 13, j + 2, k + 3, Blocks.air);
        world.setBlock(i + 13, j + 2, k + 4, Blocks.air);
        world.setBlock(i + 13, j + 2, k + 5, Blocks.air);
        world.setBlock(i + 13, j + 2, k + 6, Blocks.air);
        world.setBlock(i + 13, j + 2, k + 7, Blocks.glass_pane);
        world.setBlock(i + 13, j + 3, k + 0, ProjectFruitRegistry.lemonBrick);
        world.setBlock(i + 13, j + 3, k + 1, Blocks.bookshelf);
        world.setBlock(i + 13, j + 3, k + 2, Blocks.air);
        world.setBlock(i + 13, j + 3, k + 3, Blocks.air);
        world.setBlock(i + 13, j + 3, k + 4, Blocks.air);
        world.setBlock(i + 13, j + 3, k + 5, Blocks.air);
        world.setBlock(i + 13, j + 3, k + 6, Blocks.air);
        world.setBlock(i + 13, j + 3, k + 7, ProjectFruitRegistry.lemonBrick);
        world.setBlock(i + 13, j + 4, k + 0, ProjectFruitRegistry.lemonBrick);
        world.setBlock(i + 13, j + 4, k + 1, Blocks.planks);
        world.setBlock(i + 13, j + 4, k + 2, Blocks.planks);
        world.setBlock(i + 13, j + 4, k + 3, Blocks.planks);
        world.setBlock(i + 13, j + 4, k + 4, Blocks.planks);
        world.setBlock(i + 13, j + 4, k + 5, Blocks.planks);
        world.setBlock(i + 13, j + 4, k + 6, Blocks.planks);
        world.setBlock(i + 13, j + 4, k + 7, ProjectFruitRegistry.lemonBrick);
        world.setBlock(i + 13, j + 5, k + 0, ProjectFruitRegistry.lemonBrick);
        world.setBlock(i + 13, j + 5, k + 1, Blocks.wooden_slab);
        world.setBlock(i + 13, j + 5, k + 2, Blocks.air);
        world.setBlock(i + 13, j + 5, k + 3, Blocks.air);
        world.setBlock(i + 13, j + 5, k + 4, Blocks.air);
        world.setBlock(i + 13, j + 5, k + 5, Blocks.air);
        world.setBlock(i + 13, j + 5, k + 6, Blocks.wooden_slab);
        world.setBlock(i + 13, j + 5, k + 7, ProjectFruitRegistry.lemonBrick);
        world.setBlock(i + 13, j + 6, k + 0, ProjectFruitRegistry.lemonBrick);
        world.setBlock(i + 13, j + 6, k + 1, Blocks.wooden_slab);
        world.setBlock(i + 13, j + 6, k + 2, Blocks.air);
        world.setBlock(i + 13, j + 6, k + 3, Blocks.air);
        world.setBlock(i + 13, j + 6, k + 4, Blocks.air);
        world.setBlock(i + 13, j + 6, k + 5, Blocks.air);
        world.setBlock(i + 13, j + 6, k + 6, Blocks.wooden_slab);
        world.setBlock(i + 13, j + 6, k + 7, ProjectFruitRegistry.lemonBrick);
        world.setBlock(i + 13, j + 7, k + 0, ProjectFruitRegistry.lemonBrick);
        world.setBlock(i + 13, j + 7, k + 1, Blocks.air);
        world.setBlock(i + 13, j + 7, k + 2, Blocks.air);
        world.setBlock(i + 13, j + 7, k + 3, Blocks.air);
        world.setBlock(i + 13, j + 7, k + 4, Blocks.air);
        world.setBlock(i + 13, j + 7, k + 5, Blocks.air);
        world.setBlock(i + 13, j + 7, k + 6, Blocks.air);
        world.setBlock(i + 13, j + 7, k + 7, ProjectFruitRegistry.lemonBrick);
        world.setBlock(i + 13, j + 8, k + 0, Blocks.air);
        world.setBlock(i + 13, j + 8, k + 1, ProjectFruitRegistry.lemonBrick);
        world.setBlock(i + 13, j + 8, k + 2, Blocks.glass);
        world.setBlock(i + 13, j + 8, k + 3, Blocks.glass);
        world.setBlock(i + 13, j + 8, k + 4, Blocks.glass);
        world.setBlock(i + 13, j + 8, k + 5, Blocks.glass);
        world.setBlock(i + 13, j + 8, k + 6, ProjectFruitRegistry.lemonBrick);
        world.setBlock(i + 13, j + 8, k + 7, Blocks.air);
        world.setBlock(i + 14, j + 0, k + 0, ProjectFruitRegistry.lemonBrick);
        world.setBlock(i + 14, j + 0, k + 1, Blocks.planks);
        world.setBlock(i + 14, j + 0, k + 2, Blocks.planks);
        world.setBlock(i + 14, j + 0, k + 3, Blocks.planks);
        world.setBlock(i + 14, j + 0, k + 4, Blocks.planks);
        world.setBlock(i + 14, j + 0, k + 5, Blocks.planks);
        world.setBlock(i + 14, j + 0, k + 6, Blocks.planks);
        world.setBlock(i + 14, j + 0, k + 7, ProjectFruitRegistry.lemonBrick);
        world.setBlock(i + 14, j + 1, k + 0, ProjectFruitRegistry.lemonBrick);
        world.setBlock(i + 14, j + 1, k + 1, Blocks.log);
        world.setBlock(i + 14, j + 1, k + 2, Blocks.air);
        world.setBlock(i + 14, j + 1, k + 3, Blocks.air);
        world.setBlock(i + 14, j + 1, k + 4, Blocks.air);
        world.setBlock(i + 14, j + 1, k + 5, Blocks.air);
        world.setBlock(i + 14, j + 1, k + 6, Blocks.air);
        world.setBlock(i + 14, j + 1, k + 7, ProjectFruitRegistry.lemonBrick);
        world.setBlock(i + 14, j + 2, k + 0, ProjectFruitRegistry.lemonBrick);
        world.setBlock(i + 14, j + 2, k + 1, Blocks.air);
        world.setBlock(i + 14, j + 2, k + 2, Blocks.air);
        world.setBlock(i + 14, j + 2, k + 3, Blocks.air);
        world.setBlock(i + 14, j + 2, k + 4, Blocks.air);
        world.setBlock(i + 14, j + 2, k + 5, Blocks.air);
        world.setBlock(i + 14, j + 2, k + 6, Blocks.air);
        world.setBlock(i + 14, j + 2, k + 7, ProjectFruitRegistry.lemonBrick);
        world.setBlock(i + 14, j + 3, k + 0, ProjectFruitRegistry.lemonBrick);
        world.setBlock(i + 14, j + 3, k + 1, Blocks.bookshelf);
        world.setBlock(i + 14, j + 3, k + 2, Blocks.air);
        world.setBlock(i + 14, j + 3, k + 3, Blocks.air);
        world.setBlock(i + 14, j + 3, k + 4, Blocks.air);
        world.setBlock(i + 14, j + 3, k + 5, Blocks.air);
        world.setBlock(i + 14, j + 3, k + 6, Blocks.air);
        world.setBlock(i + 14, j + 3, k + 7, ProjectFruitRegistry.lemonBrick);
        world.setBlock(i + 14, j + 4, k + 0, ProjectFruitRegistry.lemonBrick);
        world.setBlock(i + 14, j + 4, k + 1, Blocks.planks);
        world.setBlock(i + 14, j + 4, k + 2, Blocks.planks);
        world.setBlock(i + 14, j + 4, k + 3, Blocks.planks);
        world.setBlock(i + 14, j + 4, k + 4, Blocks.planks);
        world.setBlock(i + 14, j + 4, k + 5, Blocks.planks);
        world.setBlock(i + 14, j + 4, k + 6, Blocks.planks);
        world.setBlock(i + 14, j + 4, k + 7, ProjectFruitRegistry.lemonBrick);
        world.setBlock(i + 14, j + 5, k + 0, ProjectFruitRegistry.lemonBrick);
        world.setBlock(i + 14, j + 5, k + 1, Blocks.wooden_slab);
        world.setBlock(i + 14, j + 5, k + 2, Blocks.air);
        world.setBlock(i + 14, j + 5, k + 3, Blocks.air);
        world.setBlock(i + 14, j + 5, k + 4, Blocks.air);
        world.setBlock(i + 14, j + 5, k + 5, Blocks.air);
        world.setBlock(i + 14, j + 5, k + 6, Blocks.wooden_slab);
        world.setBlock(i + 14, j + 5, k + 7, ProjectFruitRegistry.lemonBrick);
        world.setBlock(i + 14, j + 6, k + 0, ProjectFruitRegistry.lemonBrick);
        world.setBlock(i + 14, j + 6, k + 1, Blocks.wooden_slab);
        world.setBlock(i + 14, j + 6, k + 2, Blocks.air);
        world.setBlock(i + 14, j + 6, k + 3, Blocks.air);
        world.setBlock(i + 14, j + 6, k + 4, Blocks.air);
        world.setBlock(i + 14, j + 6, k + 5, Blocks.air);
        world.setBlock(i + 14, j + 6, k + 6, Blocks.wooden_slab);
        world.setBlock(i + 14, j + 6, k + 7, ProjectFruitRegistry.lemonBrick);
        world.setBlock(i + 14, j + 7, k + 0, ProjectFruitRegistry.lemonBrick);
        world.setBlock(i + 14, j + 7, k + 1, Blocks.air);
        world.setBlock(i + 14, j + 7, k + 2, Blocks.air);
        world.setBlock(i + 14, j + 7, k + 3, Blocks.air);
        world.setBlock(i + 14, j + 7, k + 4, Blocks.air);
        world.setBlock(i + 14, j + 7, k + 5, Blocks.air);
        world.setBlock(i + 14, j + 7, k + 6, Blocks.air);
        world.setBlock(i + 14, j + 7, k + 7, ProjectFruitRegistry.lemonBrick);
        world.setBlock(i + 14, j + 8, k + 0, Blocks.air);
        world.setBlock(i + 14, j + 8, k + 1, ProjectFruitRegistry.lemonBrick);
        world.setBlock(i + 14, j + 8, k + 2, ProjectFruitRegistry.lemonBrick);
        world.setBlock(i + 14, j + 8, k + 3, Blocks.glass);
        world.setBlock(i + 14, j + 8, k + 4, Blocks.glass);
        world.setBlock(i + 14, j + 8, k + 5, ProjectFruitRegistry.lemonBrick);
        world.setBlock(i + 14, j + 8, k + 6, ProjectFruitRegistry.lemonBrick);
        world.setBlock(i + 14, j + 8, k + 7, Blocks.air);
        world.setBlock(i + 15, j + 0, k + 0, ProjectFruitRegistry.lemonBrick);
        world.setBlock(i + 15, j + 0, k + 1, Blocks.planks);
        world.setBlock(i + 15, j + 0, k + 2, Blocks.planks);
        world.setBlock(i + 15, j + 0, k + 3, Blocks.planks);
        world.setBlock(i + 15, j + 0, k + 4, Blocks.planks);
        world.setBlock(i + 15, j + 0, k + 5, Blocks.planks);
        world.setBlock(i + 15, j + 0, k + 6, Blocks.planks);
        world.setBlock(i + 15, j + 0, k + 7, ProjectFruitRegistry.lemonBrick);
        world.setBlock(i + 15, j + 1, k + 0, ProjectFruitRegistry.lemonBrick);
        world.setBlock(i + 15, j + 1, k + 1, Blocks.log);
        world.setBlock(i + 15, j + 1, k + 2, Blocks.log);
        world.setBlock(i + 15, j + 1, k + 3, Blocks.furnace);
        world.setBlockMetadataWithNotify(i + 15, j + 1, k + 3, 4, 2);
        world.setBlock(i + 15, j + 1, k + 4, Blocks.crafting_table);
        world.setBlock(i + 15, j + 1, k + 5, Blocks.furnace);
        world.setBlockMetadataWithNotify(i + 15, j + 1, k + 5, 4, 2);
        world.setBlock(i + 15, j + 1, k + 6, Blocks.log);
        world.setBlock(i + 15, j + 1, k + 7, ProjectFruitRegistry.lemonBrick);
        world.setBlock(i + 15, j + 2, k + 0, ProjectFruitRegistry.lemonBrick);
        world.setBlock(i + 15, j + 2, k + 1, Blocks.glowstone);
        world.setBlock(i + 15, j + 2, k + 2, Blocks.air);
        world.setBlock(i + 15, j + 2, k + 3, Blocks.air);
        world.setBlock(i + 15, j + 2, k + 4, Blocks.air);
        world.setBlock(i + 15, j + 2, k + 5, Blocks.air);
        world.setBlock(i + 15, j + 2, k + 6, Blocks.glowstone);
        world.setBlock(i + 15, j + 2, k + 7, ProjectFruitRegistry.lemonBrick);
        world.setBlock(i + 15, j + 3, k + 0, ProjectFruitRegistry.lemonBrick);
        world.setBlock(i + 15, j + 3, k + 1, Blocks.glowstone);
        world.setBlock(i + 15, j + 3, k + 2, Blocks.bookshelf);
        world.setBlock(i + 15, j + 3, k + 3, Blocks.bookshelf);
        world.setBlock(i + 15, j + 3, k + 4, Blocks.bookshelf);
        world.setBlock(i + 15, j + 3, k + 5, Blocks.bookshelf);
        world.setBlock(i + 15, j + 3, k + 6, Blocks.bookshelf);
        world.setBlock(i + 15, j + 3, k + 7, ProjectFruitRegistry.lemonBrick);
        world.setBlock(i + 15, j + 4, k + 0, ProjectFruitRegistry.lemonBrick);
        world.setBlock(i + 15, j + 4, k + 1, Blocks.glowstone);
        world.setBlock(i + 15, j + 4, k + 2, Blocks.planks);
        world.setBlock(i + 15, j + 4, k + 3, Blocks.planks);
        world.setBlock(i + 15, j + 4, k + 4, Blocks.planks);
        world.setBlock(i + 15, j + 4, k + 5, Blocks.planks);
        world.setBlock(i + 15, j + 4, k + 6, Blocks.glowstone);
        world.setBlock(i + 15, j + 4, k + 7, ProjectFruitRegistry.lemonBrick);
        world.setBlock(i + 15, j + 5, k + 0, ProjectFruitRegistry.lemonBrick);
        world.setBlock(i + 15, j + 5, k + 1, Blocks.chest);
        world.setTileEntity(i + 15, j + 5, k + 1, chest3);
        world.setBlockMetadataWithNotify(i + 15, j + 5, k + 1, 3, 2);
        world.setBlock(i + 15, j + 5, k + 2, Blocks.air);
        world.setBlock(i + 15, j + 5, k + 3, Blocks.air);
        world.setBlock(i + 15, j + 5, k + 4, Blocks.air);
        world.setBlock(i + 15, j + 5, k + 5, Blocks.air);
        world.setBlock(i + 15, j + 5, k + 6, Blocks.chest);
        world.setTileEntity(i + 15, j + 5, k + 6, chest4);
        world.setBlockMetadataWithNotify(i + 15, j + 5, k + 6, 2, 2);
        world.setBlock(i + 15, j + 5, k + 7, ProjectFruitRegistry.lemonBrick);
        world.setBlock(i + 15, j + 6, k + 0, ProjectFruitRegistry.lemonBrick);
        world.setBlock(i + 15, j + 6, k + 1, Blocks.wooden_slab);
        world.setBlock(i + 15, j + 6, k + 2, Blocks.air);
        world.setBlock(i + 15, j + 6, k + 3, Blocks.air);
        world.setBlock(i + 15, j + 6, k + 4, Blocks.air);
        world.setBlock(i + 15, j + 6, k + 5, Blocks.air);
        world.setBlock(i + 15, j + 6, k + 6, Blocks.wooden_slab);
        world.setBlock(i + 15, j + 6, k + 7, ProjectFruitRegistry.lemonBrick);
        world.setBlock(i + 15, j + 7, k + 0, Blocks.air);
        world.setBlock(i + 15, j + 7, k + 1, ProjectFruitRegistry.lemonBrick);
        world.setBlock(i + 15, j + 7, k + 2, Blocks.air);
        world.setBlock(i + 15, j + 7, k + 3, Blocks.air);
        world.setBlock(i + 15, j + 7, k + 4, Blocks.air);
        world.setBlock(i + 15, j + 7, k + 5, Blocks.air);
        world.setBlock(i + 15, j + 7, k + 6, ProjectFruitRegistry.lemonBrick);
        world.setBlock(i + 15, j + 7, k + 7, Blocks.air);
        world.setBlock(i + 15, j + 8, k + 0, Blocks.air);
        world.setBlock(i + 15, j + 8, k + 1, Blocks.air);
        world.setBlock(i + 15, j + 8, k + 2, ProjectFruitRegistry.lemonBrick);
        world.setBlock(i + 15, j + 8, k + 3, Blocks.glowstone);
        world.setBlock(i + 15, j + 8, k + 4, Blocks.glowstone);
        world.setBlock(i + 15, j + 8, k + 5, ProjectFruitRegistry.lemonBrick);
        world.setBlock(i + 15, j + 8, k + 6, Blocks.air);
        world.setBlock(i + 15, j + 8, k + 7, Blocks.air);
        world.setBlock(i + 16, j + 0, k + 0, ProjectFruitRegistry.lemonBrick);
        world.setBlock(i + 16, j + 0, k + 1, ProjectFruitRegistry.lemonBrick);
        world.setBlock(i + 16, j + 0, k + 2, ProjectFruitRegistry.lemonBrick);
        world.setBlock(i + 16, j + 0, k + 3, ProjectFruitRegistry.lemonBrick);
        world.setBlock(i + 16, j + 0, k + 4, ProjectFruitRegistry.lemonBrick);
        world.setBlock(i + 16, j + 0, k + 5, ProjectFruitRegistry.lemonBrick);
        world.setBlock(i + 16, j + 0, k + 6, ProjectFruitRegistry.lemonBrick);
        world.setBlock(i + 16, j + 0, k + 7, ProjectFruitRegistry.lemonBrick);
        world.setBlock(i + 16, j + 1, k + 0, ProjectFruitRegistry.lemonBrick);
        world.setBlock(i + 16, j + 1, k + 1, ProjectFruitRegistry.lemonBrick);
        world.setBlock(i + 16, j + 1, k + 2, ProjectFruitRegistry.lemonBrick);
        world.setBlock(i + 16, j + 1, k + 3, ProjectFruitRegistry.lemonBrick);
        world.setBlock(i + 16, j + 1, k + 4, ProjectFruitRegistry.lemonBrick);
        world.setBlock(i + 16, j + 1, k + 5, ProjectFruitRegistry.lemonBrick);
        world.setBlock(i + 16, j + 1, k + 6, ProjectFruitRegistry.lemonBrick);
        world.setBlock(i + 16, j + 1, k + 7, ProjectFruitRegistry.lemonBrick);
        world.setBlock(i + 16, j + 2, k + 0, ProjectFruitRegistry.lemonBrick);
        world.setBlock(i + 16, j + 2, k + 1, ProjectFruitRegistry.lemonBrick);
        world.setBlock(i + 16, j + 2, k + 2, ProjectFruitRegistry.lemonBrick);
        world.setBlock(i + 16, j + 2, k + 3, ProjectFruitRegistry.lemonBrick);
        world.setBlock(i + 16, j + 2, k + 4, ProjectFruitRegistry.lemonBrick);
        world.setBlock(i + 16, j + 2, k + 5, ProjectFruitRegistry.lemonBrick);
        world.setBlock(i + 16, j + 2, k + 6, ProjectFruitRegistry.lemonBrick);
        world.setBlock(i + 16, j + 2, k + 7, ProjectFruitRegistry.lemonBrick);
        world.setBlock(i + 16, j + 3, k + 0, ProjectFruitRegistry.lemonBrick);
        world.setBlock(i + 16, j + 3, k + 1, ProjectFruitRegistry.lemonBrick);
        world.setBlock(i + 16, j + 3, k + 2, ProjectFruitRegistry.lemonBrick);
        world.setBlock(i + 16, j + 3, k + 3, ProjectFruitRegistry.lemonBrick);
        world.setBlock(i + 16, j + 3, k + 4, ProjectFruitRegistry.lemonBrick);
        world.setBlock(i + 16, j + 3, k + 5, ProjectFruitRegistry.lemonBrick);
        world.setBlock(i + 16, j + 3, k + 6, ProjectFruitRegistry.lemonBrick);
        world.setBlock(i + 16, j + 3, k + 7, ProjectFruitRegistry.lemonBrick);
        world.setBlock(i + 16, j + 4, k + 0, ProjectFruitRegistry.lemonBrick);
        world.setBlock(i + 16, j + 4, k + 1, Blocks.planks);
        world.setBlock(i + 16, j + 4, k + 2, Blocks.planks);
        world.setBlock(i + 16, j + 4, k + 3, Blocks.planks);
        world.setBlock(i + 16, j + 4, k + 4, Blocks.planks);
        world.setBlock(i + 16, j + 4, k + 5, Blocks.planks);
        world.setBlock(i + 16, j + 4, k + 6, Blocks.planks);
        world.setBlock(i + 16, j + 4, k + 7, ProjectFruitRegistry.lemonBrick);
        world.setBlock(i + 16, j + 5, k + 0, ProjectFruitRegistry.lemonBrick);
        world.setBlock(i + 16, j + 5, k + 1, Blocks.bookshelf);
        world.setBlock(i + 16, j + 5, k + 2, Blocks.air);
        world.setBlock(i + 16, j + 5, k + 3, Blocks.bed, 3, 0);
        world.setBlock(i + 16, j + 5, k + 4, Blocks.bed, 3, 0);
        world.setBlock(i + 16, j + 5, k + 5, Blocks.air);
        world.setBlock(i + 16, j + 5, k + 6, Blocks.bookshelf);
        world.setBlock(i + 16, j + 5, k + 7, ProjectFruitRegistry.lemonBrick);
        world.setBlock(i + 16, j + 6, k + 0, Blocks.air);
        world.setBlock(i + 16, j + 6, k + 1, ProjectFruitRegistry.lemonBrick);
        world.setBlock(i + 16, j + 6, k + 2, Blocks.air);
        world.setBlock(i + 16, j + 6, k + 3, Blocks.air);
        world.setBlock(i + 16, j + 6, k + 4, Blocks.air);
        world.setBlock(i + 16, j + 6, k + 5, Blocks.air);
        world.setBlock(i + 16, j + 6, k + 6, ProjectFruitRegistry.lemonBrick);
        world.setBlock(i + 16, j + 6, k + 7, Blocks.air);
        world.setBlock(i + 16, j + 7, k + 0, Blocks.air);
        world.setBlock(i + 16, j + 7, k + 1, Blocks.air);
        world.setBlock(i + 16, j + 7, k + 2, ProjectFruitRegistry.lemonBrick);
        world.setBlock(i + 16, j + 7, k + 3, Blocks.air);
        world.setBlock(i + 16, j + 7, k + 4, Blocks.air);
        world.setBlock(i + 16, j + 7, k + 5, ProjectFruitRegistry.lemonBrick);
        world.setBlock(i + 16, j + 7, k + 6, Blocks.air);
        world.setBlock(i + 16, j + 7, k + 7, Blocks.air);
        world.setBlock(i + 16, j + 8, k + 0, Blocks.air);
        world.setBlock(i + 16, j + 8, k + 1, Blocks.air);
        world.setBlock(i + 16, j + 8, k + 2, Blocks.air);
        world.setBlock(i + 16, j + 8, k + 3, ProjectFruitRegistry.lemonBrick);
        world.setBlock(i + 16, j + 8, k + 4, ProjectFruitRegistry.lemonBrick);
        world.setBlock(i + 16, j + 8, k + 5, Blocks.air);
        world.setBlock(i + 16, j + 8, k + 6, Blocks.air);
        world.setBlock(i + 16, j + 8, k + 7, Blocks.air);
        world.setBlock(i + 17, j + 0, k + 7, Blocks.air);
        world.setBlock(i + 17, j + 1, k + 3, ProjectFruitRegistry.lemonBrick);
        world.setBlock(i + 17, j + 1, k + 4, ProjectFruitRegistry.lemonBrick);
        world.setBlock(i + 17, j + 1, k + 7, Blocks.air);
        world.setBlock(i + 17, j + 2, k + 2, ProjectFruitRegistry.lemonBrick);
        world.setBlock(i + 17, j + 2, k + 3, ProjectFruitRegistry.lemonBrick);
        world.setBlock(i + 17, j + 2, k + 4, ProjectFruitRegistry.lemonBrick);
        world.setBlock(i + 17, j + 2, k + 5, ProjectFruitRegistry.lemonBrick);
        world.setBlock(i + 17, j + 2, k + 7, Blocks.air);
        world.setBlock(i + 17, j + 3, k + 1, ProjectFruitRegistry.lemonBrick);
        world.setBlock(i + 17, j + 3, k + 2, ProjectFruitRegistry.lemonBrick);
        world.setBlock(i + 17, j + 3, k + 3, ProjectFruitRegistry.lemonBrick);
        world.setBlock(i + 17, j + 3, k + 4, ProjectFruitRegistry.lemonBrick);
        world.setBlock(i + 17, j + 3, k + 5, ProjectFruitRegistry.lemonBrick);
        world.setBlock(i + 17, j + 3, k + 6, ProjectFruitRegistry.lemonBrick);
        world.setBlock(i + 17, j + 3, k + 7, Blocks.air);
        world.setBlock(i + 17, j + 4, k + 0, ProjectFruitRegistry.lemonBrick);
        world.setBlock(i + 17, j + 4, k + 1, ProjectFruitRegistry.lemonBrick);
        world.setBlock(i + 17, j + 4, k + 2, Blocks.planks);
        world.setBlock(i + 17, j + 4, k + 3, Blocks.planks);
        world.setBlock(i + 17, j + 4, k + 4, Blocks.planks);
        world.setBlock(i + 17, j + 4, k + 5, Blocks.planks);
        world.setBlock(i + 17, j + 4, k + 6, ProjectFruitRegistry.lemonBrick);
        world.setBlock(i + 17, j + 4, k + 7, ProjectFruitRegistry.lemonBrick);
        world.setBlock(i + 17, j + 5, k + 0, Blocks.air);
        world.setBlock(i + 17, j + 5, k + 1, ProjectFruitRegistry.lemonBrick);
        world.setBlock(i + 17, j + 5, k + 2, Blocks.bookshelf);
        world.setBlock(i + 17, j + 5, k + 3, Blocks.bed, 11, 0);
        world.setBlock(i + 17, j + 5, k + 4, Blocks.bed, 11, 0);
        world.setBlock(i + 17, j + 5, k + 5, Blocks.bookshelf);
        world.setBlock(i + 17, j + 5, k + 6, ProjectFruitRegistry.lemonBrick);
        world.setBlock(i + 17, j + 5, k + 7, Blocks.air);
        world.setBlock(i + 17, j + 6, k + 0, Blocks.air);
        world.setBlock(i + 17, j + 6, k + 1, Blocks.air);
        world.setBlock(i + 17, j + 6, k + 2, ProjectFruitRegistry.lemonBrick);
        world.setBlock(i + 17, j + 6, k + 3, Blocks.air);
        world.setBlock(i + 17, j + 6, k + 4, Blocks.air);
        world.setBlock(i + 17, j + 6, k + 5, ProjectFruitRegistry.lemonBrick);
        world.setBlock(i + 17, j + 6, k + 6, Blocks.air);
        world.setBlock(i + 17, j + 6, k + 7, Blocks.air);
        world.setBlock(i + 17, j + 7, k + 0, Blocks.air);
        world.setBlock(i + 17, j + 7, k + 1, Blocks.air);
        world.setBlock(i + 17, j + 7, k + 2, Blocks.air);
        world.setBlock(i + 17, j + 7, k + 3, ProjectFruitRegistry.lemonBrick);
        world.setBlock(i + 17, j + 7, k + 4, ProjectFruitRegistry.lemonBrick);
        world.setBlock(i + 17, j + 7, k + 5, Blocks.air);
        world.setBlock(i + 17, j + 7, k + 6, Blocks.air);
        world.setBlock(i + 17, j + 7, k + 7, Blocks.air);
        world.setBlock(i + 17, j + 8, k + 0, Blocks.air);
        world.setBlock(i + 17, j + 8, k + 1, Blocks.air);
        world.setBlock(i + 17, j + 8, k + 2, Blocks.air);
        world.setBlock(i + 17, j + 8, k + 3, Blocks.air);
        world.setBlock(i + 17, j + 8, k + 4, Blocks.air);
        world.setBlock(i + 17, j + 8, k + 5, Blocks.air);
        world.setBlock(i + 17, j + 8, k + 6, Blocks.air);
        world.setBlock(i + 17, j + 8, k + 7, Blocks.air);
        world.setBlock(i + 18, j + 0, k + 7, Blocks.air);
        world.setBlock(i + 18, j + 1, k + 7, Blocks.air);
        world.setBlock(i + 18, j + 2, k + 3, ProjectFruitRegistry.lemonBrick);
        world.setBlock(i + 18, j + 2, k + 4, ProjectFruitRegistry.lemonBrick);
        world.setBlock(i + 18, j + 2, k + 7, Blocks.air);
        world.setBlock(i + 18, j + 3, k + 2, ProjectFruitRegistry.lemonBrick);
        world.setBlock(i + 18, j + 3, k + 3, ProjectFruitRegistry.lemonBrick);
        world.setBlock(i + 18, j + 3, k + 4, ProjectFruitRegistry.lemonBrick);
        world.setBlock(i + 18, j + 3, k + 5, ProjectFruitRegistry.lemonBrick);
        world.setBlock(i + 18, j + 3, k + 7, Blocks.air);
        world.setBlock(i + 18, j + 4, k + 0, Blocks.air);
        world.setBlock(i + 18, j + 4, k + 1, ProjectFruitRegistry.lemonBrick);
        world.setBlock(i + 18, j + 4, k + 2, ProjectFruitRegistry.lemonBrick);
        world.setBlock(i + 18, j + 4, k + 3, Blocks.planks);
        world.setBlock(i + 18, j + 4, k + 4, Blocks.planks);
        world.setBlock(i + 18, j + 4, k + 5, ProjectFruitRegistry.lemonBrick);
        world.setBlock(i + 18, j + 4, k + 6, ProjectFruitRegistry.lemonBrick);
        world.setBlock(i + 18, j + 4, k + 7, Blocks.air);
        world.setBlock(i + 18, j + 5, k + 0, Blocks.air);
        world.setBlock(i + 18, j + 5, k + 1, Blocks.air);
        world.setBlock(i + 18, j + 5, k + 2, ProjectFruitRegistry.lemonBrick);
        world.setBlock(i + 18, j + 5, k + 3, Blocks.bookshelf);
        world.setBlock(i + 18, j + 5, k + 4, Blocks.bookshelf);
        world.setBlock(i + 18, j + 5, k + 5, ProjectFruitRegistry.lemonBrick);
        world.setBlock(i + 18, j + 5, k + 6, Blocks.air);
        world.setBlock(i + 18, j + 5, k + 7, Blocks.air);
        world.setBlock(i + 18, j + 6, k + 0, Blocks.air);
        world.setBlock(i + 18, j + 6, k + 1, Blocks.air);
        world.setBlock(i + 18, j + 6, k + 2, Blocks.air);
        world.setBlock(i + 18, j + 6, k + 3, ProjectFruitRegistry.lemonBrick);
        world.setBlock(i + 18, j + 6, k + 4, ProjectFruitRegistry.lemonBrick);
        world.setBlock(i + 18, j + 6, k + 5, Blocks.air);
        world.setBlock(i + 18, j + 6, k + 6, Blocks.air);
        world.setBlock(i + 18, j + 6, k + 7, Blocks.air);
        world.setBlock(i + 18, j + 7, k + 0, Blocks.air);
        world.setBlock(i + 18, j + 7, k + 1, Blocks.air);
        world.setBlock(i + 18, j + 7, k + 2, Blocks.air);
        world.setBlock(i + 18, j + 7, k + 3, Blocks.air);
        world.setBlock(i + 18, j + 7, k + 4, Blocks.air);
        world.setBlock(i + 18, j + 7, k + 5, Blocks.air);
        world.setBlock(i + 18, j + 7, k + 6, Blocks.air);
        world.setBlock(i + 18, j + 7, k + 7, Blocks.air);
        world.setBlock(i + 18, j + 8, k + 0, Blocks.air);
        world.setBlock(i + 18, j + 8, k + 1, Blocks.air);
        world.setBlock(i + 18, j + 8, k + 2, Blocks.air);
        world.setBlock(i + 18, j + 8, k + 3, Blocks.air);
        world.setBlock(i + 18, j + 8, k + 4, Blocks.air);
        world.setBlock(i + 18, j + 8, k + 5, Blocks.air);
        world.setBlock(i + 18, j + 8, k + 6, Blocks.air);
        world.setBlock(i + 18, j + 8, k + 7, Blocks.air);
        world.setBlock(i + 19, j + 0, k + 7, Blocks.air);
        world.setBlock(i + 19, j + 1, k + 7, Blocks.air);
        world.setBlock(i + 19, j + 2, k + 7, Blocks.air);
        world.setBlock(i + 19, j + 3, k + 3, ProjectFruitRegistry.lemonBrick);
        world.setBlock(i + 19, j + 3, k + 4, ProjectFruitRegistry.lemonBrick);
        world.setBlock(i + 19, j + 3, k + 7, Blocks.air);
        world.setBlock(i + 19, j + 4, k + 0, Blocks.air);
        world.setBlock(i + 19, j + 4, k + 1, Blocks.air);
        world.setBlock(i + 19, j + 4, k + 2, ProjectFruitRegistry.lemonBrick);
        world.setBlock(i + 19, j + 4, k + 3, ProjectFruitRegistry.lemonBrick);
        world.setBlock(i + 19, j + 4, k + 4, ProjectFruitRegistry.lemonBrick);
        world.setBlock(i + 19, j + 4, k + 5, ProjectFruitRegistry.lemonBrick);
        world.setBlock(i + 19, j + 4, k + 6, Blocks.air);
        world.setBlock(i + 19, j + 4, k + 7, Blocks.air);
        world.setBlock(i + 19, j + 5, k + 0, Blocks.air);
        world.setBlock(i + 19, j + 5, k + 1, Blocks.air);
        world.setBlock(i + 19, j + 5, k + 2, Blocks.air);
        world.setBlock(i + 19, j + 5, k + 3, ProjectFruitRegistry.lemonBrick);
        world.setBlock(i + 19, j + 5, k + 4, ProjectFruitRegistry.lemonBrick);
        world.setBlock(i + 19, j + 5, k + 5, Blocks.air);
        world.setBlock(i + 19, j + 5, k + 6, Blocks.air);
        world.setBlock(i + 19, j + 5, k + 7, Blocks.air);
        world.setBlock(i + 19, j + 6, k + 0, Blocks.air);
        world.setBlock(i + 19, j + 6, k + 1, Blocks.air);
        world.setBlock(i + 19, j + 6, k + 2, Blocks.air);
        world.setBlock(i + 19, j + 6, k + 3, Blocks.air);
        world.setBlock(i + 19, j + 6, k + 4, Blocks.air);
        world.setBlock(i + 19, j + 6, k + 5, Blocks.air);
        world.setBlock(i + 19, j + 6, k + 6, Blocks.air);
        world.setBlock(i + 19, j + 6, k + 7, Blocks.air);
        world.setBlock(i + 19, j + 7, k + 0, Blocks.air);
        world.setBlock(i + 19, j + 7, k + 1, Blocks.air);
        world.setBlock(i + 19, j + 7, k + 2, Blocks.air);
        world.setBlock(i + 19, j + 7, k + 3, Blocks.air);
        world.setBlock(i + 19, j + 7, k + 4, Blocks.air);
        world.setBlock(i + 19, j + 7, k + 5, Blocks.air);
        world.setBlock(i + 19, j + 7, k + 6, Blocks.air);
        world.setBlock(i + 19, j + 7, k + 7, Blocks.air);
        world.setBlock(i + 19, j + 8, k + 0, Blocks.air);
        world.setBlock(i + 19, j + 8, k + 1, Blocks.air);
        world.setBlock(i + 19, j + 8, k + 2, Blocks.air);
        world.setBlock(i + 19, j + 8, k + 3, Blocks.air);
        world.setBlock(i + 19, j + 8, k + 4, Blocks.air);
        world.setBlock(i + 19, j + 8, k + 5, Blocks.air);
        world.setBlock(i + 19, j + 8, k + 6, Blocks.air);
        world.setBlock(i + 19, j + 8, k + 7, Blocks.air);
        world.setBlock(i + 20, j + 0, k + 0, Blocks.air);
        world.setBlock(i + 20, j + 0, k + 1, Blocks.air);
        world.setBlock(i + 20, j + 0, k + 2, Blocks.air);
        world.setBlock(i + 20, j + 0, k + 3, Blocks.air);
        world.setBlock(i + 20, j + 0, k + 4, Blocks.air);
        world.setBlock(i + 20, j + 0, k + 5, Blocks.air);
        world.setBlock(i + 20, j + 0, k + 6, Blocks.air);
        world.setBlock(i + 20, j + 0, k + 7, Blocks.air);
        world.setBlock(i + 20, j + 1, k + 0, Blocks.air);
        world.setBlock(i + 20, j + 1, k + 1, Blocks.air);
        world.setBlock(i + 20, j + 1, k + 2, Blocks.air);
        world.setBlock(i + 20, j + 1, k + 3, Blocks.air);
        world.setBlock(i + 20, j + 1, k + 4, Blocks.air);
        world.setBlock(i + 20, j + 1, k + 5, Blocks.air);
        world.setBlock(i + 20, j + 1, k + 6, Blocks.air);
        world.setBlock(i + 20, j + 1, k + 7, Blocks.air);
        world.setBlock(i + 20, j + 2, k + 0, Blocks.air);
        world.setBlock(i + 20, j + 2, k + 1, Blocks.air);
        world.setBlock(i + 20, j + 2, k + 2, Blocks.air);
        world.setBlock(i + 20, j + 2, k + 3, Blocks.air);
        world.setBlock(i + 20, j + 2, k + 4, Blocks.air);
        world.setBlock(i + 20, j + 2, k + 5, Blocks.air);
        world.setBlock(i + 20, j + 2, k + 6, Blocks.air);
        world.setBlock(i + 20, j + 2, k + 7, Blocks.air);
        world.setBlock(i + 20, j + 3, k + 0, Blocks.air);
        world.setBlock(i + 20, j + 3, k + 1, Blocks.air);
        world.setBlock(i + 20, j + 3, k + 2, Blocks.air);
        world.setBlock(i + 20, j + 3, k + 3, Blocks.air);
        world.setBlock(i + 20, j + 3, k + 4, Blocks.air);
        world.setBlock(i + 20, j + 3, k + 5, Blocks.air);
        world.setBlock(i + 20, j + 3, k + 6, Blocks.air);
        world.setBlock(i + 20, j + 3, k + 7, Blocks.air);
        world.setBlock(i + 20, j + 4, k + 0, Blocks.air);
        world.setBlock(i + 20, j + 4, k + 1, Blocks.air);
        world.setBlock(i + 20, j + 4, k + 2, Blocks.air);
        world.setBlock(i + 20, j + 4, k + 3, ProjectFruitRegistry.lemonBrick);
        world.setBlock(i + 20, j + 4, k + 4, ProjectFruitRegistry.lemonBrick);
        world.setBlock(i + 20, j + 4, k + 5, Blocks.air);
        world.setBlock(i + 20, j + 4, k + 6, Blocks.air);
        world.setBlock(i + 20, j + 4, k + 7, Blocks.air);
        world.setBlock(i + 20, j + 5, k + 0, Blocks.air);
        world.setBlock(i + 20, j + 5, k + 1, Blocks.air);
        world.setBlock(i + 20, j + 5, k + 2, Blocks.air);
        world.setBlock(i + 20, j + 5, k + 3, Blocks.air);
        world.setBlock(i + 20, j + 5, k + 4, Blocks.air);
        world.setBlock(i + 20, j + 5, k + 5, Blocks.air);
        world.setBlock(i + 20, j + 5, k + 6, Blocks.air);
        world.setBlock(i + 20, j + 5, k + 7, Blocks.air);
        world.setBlock(i + 20, j + 6, k + 0, Blocks.air);
        world.setBlock(i + 20, j + 6, k + 1, Blocks.air);
        world.setBlock(i + 20, j + 6, k + 2, Blocks.air);
        world.setBlock(i + 20, j + 6, k + 3, Blocks.air);
        world.setBlock(i + 20, j + 6, k + 4, Blocks.air);
        world.setBlock(i + 20, j + 6, k + 5, Blocks.air);
        world.setBlock(i + 20, j + 6, k + 6, Blocks.air);
        world.setBlock(i + 20, j + 6, k + 7, Blocks.air);
        world.setBlock(i + 20, j + 7, k + 0, Blocks.air);
        world.setBlock(i + 20, j + 7, k + 1, Blocks.air);
        world.setBlock(i + 20, j + 7, k + 2, Blocks.air);
        world.setBlock(i + 20, j + 7, k + 3, Blocks.air);
        world.setBlock(i + 20, j + 7, k + 4, Blocks.air);
        world.setBlock(i + 20, j + 7, k + 5, Blocks.air);
        world.setBlock(i + 20, j + 7, k + 6, Blocks.air);
        world.setBlock(i + 20, j + 7, k + 7, Blocks.air);
        world.setBlock(i + 20, j + 8, k + 0, Blocks.air);
        world.setBlock(i + 20, j + 8, k + 1, Blocks.air);
        world.setBlock(i + 20, j + 8, k + 2, Blocks.air);
        world.setBlock(i + 20, j + 8, k + 3, Blocks.air);
        world.setBlock(i + 20, j + 8, k + 4, Blocks.air);
        world.setBlock(i + 20, j + 8, k + 5, Blocks.air);
        world.setBlock(i + 20, j + 8, k + 6, Blocks.air);
        world.setBlock(i + 20, j + 8, k + 7, Blocks.air);
        world.setBlock(i + 10, j + 1, k + 7, Blocks.wooden_door, 3, 0);
        world.setBlock(i + 10, j + 2, k + 7, Blocks.wooden_door, 8, 0);

        return true;
    }
}